Workbook

Sheet Assumption
A1: MHP Model - Land (Major) vs POH (Minor)
A2: Land = tenants bring own homes, POH = park provides homes
A3: PLACEHOLDER INPUTS - replace every blue cell with your own deal data before using any output.
A4: Structure | B4: Actual Units | C4: Lot Rent ($/mo) | D4: Home Rent ($/mo) | E4: Comments
A5: Lot Rent - Occupied | B5: 17 | C5: 275
A6: Lot Rent - Vacant | B6: 14
A7: RTO | B7: 20 | C7: 275 | D7: 370.6
A8: POH - Occupied | B8: 8 | C8: 275 | D8: 228.125
A9: POH - Vacant | B9: 9
A10: Office - Occupied | B10: 1 | D10: 500
A11: Office - Vacant
A12: Studio - Occupied
A13: Studio - Vacant
A14: SFR - Occupied
A15: SFR - Vacant
A16: SFH - Occupied
A17: SFH - Vacant
A18: RV - Occupied
A19: RV - Vacant
A20: Total | B20: =SUM(B5:B17) -> 69 | C20: =AVERAGE(C5:C13) -> 275 | D20: =AVERAGE(D5:D17) -> 366.24167 | E20: Averages are reference only; model uses the rates above directly.

Sheet BOV 
A1: BOV Summary
A3: KEY PERFORMANCE INDICATORS | B3: Base case | C3: Worst case | D3: Best case
A4: Income
A5: Park Value | B5: 1365250.3 | C5: =B5+$B$40 -> 1565250.3 | D5: =B5-$B$40 -> 1165250.3
A6: 10000 | B6: =A6*(Assumption!B8+Assumption!B9+20) -> 370000 | C6: =$B$6 -> 370000 | D6: =$B$6 -> 370000
A7: Total Value | B7: =B5+B6 -> 1735250.3 | C7: =C5+C6 -> 1935250.3 | D7: =D5+D6 -> 1535250.3
A8: Investment Performance
A9: Unlevered IRR | B9: ='Cash Flow Model'!B43 -> 0.18086651 | C9: =IRR(_xlfn.HSTACK(-(B7+200000),'Cash Flow Model'!C40:L40)) -> 0.16296348 | D9: =IRR(_xlfn.HSTACK(-(B7-200000),'Cash Flow Model'!C40:L40)) -> 0.20186167
A10: Cash-on-Cash (Year 1) | B10: ='Cash Flow Model'!$C$24/'BOV '!B28 -> 0.15983506 | C10: ='Cash Flow Model'!$C$24/'BOV '!C28 -> 0.14331677 | D10: ='Cash Flow Model'!$C$24/'BOV '!D28 -> 0.18065708
A11: Cash-on-Cash (Avg.) | B11: ='Cash Flow Model'!B46 -> 0.23113404 | C11: =(SUMPRODUCT(('Cash Flow Model'!$C$38:$L$38<=$B$39)*'Cash Flow Model'!$C$19:$L$19)-C26)/$B$39/C28 -> 0.18776977 | D11: =(SUMPRODUCT(('Cash Flow Model'!$C$38:$L$38<=$B$39)*'Cash Flow Model'!$C$19:$L$19)-D26)/$B$39/D28 -> 0.28579661
A12: DSCR (Year 1) | B12: =B27/B24 -> 1.2552615 | C12: =C27/C24 -> 1.1255355 | D12: =D27/D24 -> 1.4187868
A13: DSCR Test (vs. requirement) | B13: =IF(B12>=$B$32,"PASS","FAIL") -> PASS | C13: =IF(C12>=$B$32-0.00001,"PASS","FAIL") -> FAIL | D13: =IF(D12>=$B$32-0.00001,"PASS","FAIL") -> PASS
A14: Equity Multiple | B14: ='Cash Flow Model'!B44 -> 8.4972883 | C14: =(SUM('Cash Flow Model'!$C$39:$L$39)-(C26-$B$26)-(C29-$B$29))/C28 -> 7.2183768 | D14: =(SUM('Cash Flow Model'!$C$39:$L$39)-(D26-$B$26)-(D29-$B$29))/D28 -> 10.109412
A15: Valuation Ratios (move with price)
A16: Going-in Cap Rate (NOI Year 1 / Price) | B16: =B27/B7 -> 0.070973579 | C16: =C27/C7 -> 0.063638757 | D16: =D27/D7 -> 0.080219443
A17: Debt Yield (NOI Year 1 / Loan) | B17: =B27/B21 -> 0.10139083 | C17: =C27/C21 -> 0.09091251 | D17: =D27/D21 -> 0.1145992
A18: Price per Unit | B18: =B7/Land!$O$30 -> 25148.555 | C18: =C7/Land!$O$30 -> 28047.105 | D18: =D7/Land!$O$30 -> 22250.004
A19: Debt
A20: LTV | B20: 0.7 | C20: =$B$20 -> 0.7 | D20: =$B$20 -> 0.7
A21: Loan Amount | B21: =B20*B7 -> 1214675.2 | C21: =C20*C7 -> 1354675.2 | D21: =D20*D7 -> 1074675.2
A22: Interest Rate | B22: =$B$35 -> 0.07023 | C22: =$B$35 -> 0.07023 | D22: =$B$35 -> 0.07023
A23: Interest Amount (Year 1) | B23: =B21*B22 -> 85306.638 | C23: =C21*C22 -> 95138.838 | D23: =D21*D22 -> 75474.438
A24: Debt Service (Year 1) | B24: =IF($B$37>=1,B23,B25) -> 98112.565 | C24: =IF($B$37>=1,C23,C25) -> 109420.74 | D24: =IF($B$37>=1,D23,D25) -> 86804.39
A25: Debt Service after IO Period | B25: =-PMT(B22,$B$36,B21) -> 98112.565 | C25: =-PMT(C22,$B$36,C21) -> 109420.74 | D25: =-PMT(D22,$B$36,D21) -> 86804.39
A26: Total Debt Service over Hold | B26: =MIN($B$37,$B$39)*B23+MAX($B$39-$B$37,0)*B25 -> 981125.65 | C26: =MIN($B$37,$B$39)*C23+MAX($B$39-$B$37,0)*C25 -> 1094207.4 | D26: =MIN($B$37,$B$39)*D23+MAX($B$39-$B$37,0)*D25 -> 868043.9
A27: NOI | B27: =Land!C64 -> 123156.92 | C27: =$B$27 -> 123156.92 | D27: =$B$27 -> 123156.92
A28: Equity Invested | B28: =B7-B21 -> 520575.08 | C28: =C7-C21 -> 580575.08 | D28: =D7-D21 -> 460575.08
A29: Loan Balance at Sale | B29: ='Cash Flow Model'!B33 -> 1037550.4 | C29: =IF($B$37>=$B$39,C21,C21*(1+C22)^($B$39-$B$37)-C25*((1+C22)^($B$39-$B$37)-1)/C22) -> 1157135.5 | D29: =IF($B$37>=$B$39,D21,D21*(1+D22)^($B$39-$B$37)-D25*((1+D22)^($B$39-$B$37)-1)/D22) -> 917965.33
A31: OTHER INPUTS
A32: DSCR Requirement | B32: 1.25
A33: SOFR | B33: 0.04023
A34: Spread | B34: 0.03
A35: Interest Rate (SOFR + Spread) | B35: =B33+B34 -> 0.07023
A36: Amortization (Years) | B36: 30
A37: Interest-Only Period (Years: 0, 1 or 2) | B37: 0
A38: POH Cap Rate | B38: 0.1
A39: Hold Period (Years) | B39: 10
A40: Price Step for Worst / Best Cases | B40: 200000

Sheet Land
A1: Land - Lot Only (Major Income)
A2: Occupancy ramps by Lease-Up/Yr (col P) up to Total Units (col O). Revenue = potential less vacancy less bad debt.
A3: Head / Category | B3: 2018 | C3: Year 1 Occupied | D3: Year 2 Occupied | E3: Year 3 Occupied | F3: Year 4 Occupied | G3: Year 5 Occupied | H3: Year 6 Occupied | I3: Year 7 Occupied | J3: Year 8 Occupied | K3: Year 9 Occupied | L3: Year 10 Occupied | N3: Base Year Vacant | O3: Total Units | P3: Lease-Up / Yr
A5: Occupied Lots | B5: =Assumption!B5+Assumption!B8+Assumption!B7 -> 45 | C5: =MIN($O5,B5+$P5) -> 47 | D5: =MIN($O5,C5+$P5) -> 49 | E5: =MIN($O5,D5+$P5) -> 51 | F5: =MIN($O5,E5+$P5) -> 53 | G5: =MIN($O5,F5+$P5) -> 55 | H5: =MIN($O5,G5+$P5) -> 57 | I5: =MIN($O5,H5+$P5) -> 59 | J5: =MIN($O5,I5+$P5) -> 61 | ... L5: =MIN($O5,K5+$P5) -> 65 | N5: =O5-B5 -> 23 | O5: =SUM(Assumption!B5:B9) -> 68 | P5: 2
A6: Occupancy | B6: =B5/SUM(Assumption!$B$5:$B$9) -> 0.66176471 | C6: =C5/SUM(Assumption!$B$5:$B$9) -> 0.69117647 | D6: =D5/SUM(Assumption!$B$5:$B$9) -> 0.72058824 | E6: =E5/SUM(Assumption!$B$5:$B$9) -> 0.75 | F6: =F5/SUM(Assumption!$B$5:$B$9) -> 0.77941176 | G6: =G5/SUM(Assumption!$B$5:$B$9) -> 0.80882353 | H6: =H5/SUM(Assumption!$B$5:$B$9) -> 0.83823529 | I6: =I5/SUM(Assumption!$B$5:$B$9) -> 0.86764706 | ... L6: =L5/SUM(Assumption!$B$5:$B$9) -> 0.95588235
A7: Average Rent | B7: =AVERAGE(Assumption!C5,Assumption!C7,Assumption!C8) -> 275 | C7: =B7*(1+$N$34) -> 288.75 | D7: =C7*(1+$N$34) -> 303.1875 | E7: =D7*(1+$N$34) -> 318.34688 | F7: =E7*(1+$N$34) -> 334.26422 | G7: =F7*(1+$N$34) -> 350.97743 | H7: =G7*(1+$N$34) -> 368.5263 | I7: =H7*(1+$N$34) -> 386.95262 | J7: =I7*(1+$N$34) -> 406.30025 | ... L7: =K7*(1+$N$34) -> 447.94602
A8: Rent Increase (%) | C8: =(C7-B7)/C7 -> 0.047619048 | D8: =(D7-C7)/D7 -> 0.047619048 | E8: =(E7-D7)/E7 -> 0.047619048 | F8: =(F7-E7)/F7 -> 0.047619048 | G8: =(G7-F7)/G7 -> 0.047619048 | H8: =(H7-G7)/H7 -> 0.047619048 | I8: =(I7-H7)/I7 -> 0.047619048 | J8: =(J7-I7)/J7 -> 0.047619048 | ... L8: =(L7-K7)/L7 -> 0.047619048
A10: Occupied Office | B10: =Assumption!B10 -> 1 | C10: =MIN($O10,B10+$P10) -> 1 | D10: =MIN($O10,C10+$P10) -> 1 | E10: =MIN($O10,D10+$P10) -> 1 | F10: =MIN($O10,E10+$P10) -> 1 | G10: =MIN($O10,F10+$P10) -> 1 | H10: =MIN($O10,G10+$P10) -> 1 | I10: =MIN($O10,H10+$P10) -> 1 | J10: =MIN($O10,I10+$P10) -> 1 | ... L10: =MIN($O10,K10+$P10) -> 1 | N10: =O10-B10 -> 0 | O10: =Assumption!B10+Assumption!B11 -> 1 | P10: 1
A11: Occupancy | B11: =B10/SUM(Assumption!$B$10:$B$11) -> 1 | C11: =C10/SUM(Assumption!$B$10:$B$11) -> 1 | D11: =D10/SUM(Assumption!$B$10:$B$11) -> 1 | E11: =E10/SUM(Assumption!$B$10:$B$11) -> 1 | F11: =F10/SUM(Assumption!$B$10:$B$11) -> 1 | G11: =G10/SUM(Assumption!$B$10:$B$11) -> 1 | H11: =H10/SUM(Assumption!$B$10:$B$11) -> 1 | I11: =I10/SUM(Assumption!$B$10:$B$11) -> 1 | ... L11: =L10/SUM(Assumption!$B$10:$B$11) -> 1
A12: Average Rent | B12: =Assumption!D10 -> 500 | C12: =B12*(1+$N$35) -> 525 | D12: =C12*(1+$N$35) -> 551.25 | E12: =D12*(1+$N$35) -> 578.8125 | F12: =E12*(1+$N$35) -> 607.75313 | G12: =F12*(1+$N$35) -> 638.14078 | H12: =G12*(1+$N$35) -> 670.04782 | I12: =H12*(1+$N$35) -> 703.55021 | J12: =I12*(1+$N$35) -> 738.72772 | ... L12: =K12*(1+$N$35) -> 814.44731
A13: Rent Increase (%) | C13: =(C12-B12)/C12 -> 0.047619048 | D13: =(D12-C12)/D12 -> 0.047619048 | E13: =(E12-D12)/E12 -> 0.047619048 | F13: =(F12-E12)/F12 -> 0.047619048 | G13: =(G12-F12)/G12 -> 0.047619048 | H13: =(H12-G12)/H12 -> 0.047619048 | I13: =(I12-H12)/I12 -> 0.047619048 | J13: =(J12-I12)/J12 -> 0.047619048 | ... L13: =(L12-K12)/L12 -> 0.047619048
A15: Occupied Studio | B15: =Assumption!B12 -> 0 | C15: =MIN($O15,B15+$P15) -> 0 | D15: =MIN($O15,C15+$P15) -> 0 | E15: =MIN($O15,D15+$P15) -> 0 | F15: =MIN($O15,E15+$P15) -> 0 | G15: =MIN($O15,F15+$P15) -> 0 | H15: =MIN($O15,G15+$P15) -> 0 | I15: =MIN($O15,H15+$P15) -> 0 | J15: =MIN($O15,I15+$P15) -> 0 | ... L15: =MIN($O15,K15+$P15) -> 0 | N15: =O15-B15 -> 0 | O15: =Assumption!B12+Assumption!B13 -> 0 | P15: 1
A16: Occupancy | B16: =B15/SUM(Assumption!B12:$B$13) -> #DIV/0! | C16: =C15/SUM(Assumption!$B$12:$C$13) -> #DIV/0! | D16: =D15/SUM(Assumption!$B$12:$C$13) -> #DIV/0! | E16: =E15/SUM(Assumption!$B$12:$C$13) -> #DIV/0! | F16: =F15/SUM(Assumption!$B$12:$C$13) -> #DIV/0! | G16: =G15/SUM(Assumption!$B$12:$C$13) -> #DIV/0! | H16: =H15/SUM(Assumption!$B$12:$C$13) -> #DIV/0! | I16: =I15/SUM(Assumption!$B$12:$C$13) -> #DIV/0! | J16: =J15/SUM(Assumption!$B$12:$C$13) -> #DIV/0! | ... L16: =L15/SUM(Assumption!$B$12:$C$13) -> #DIV/0!
A17: Average Rent | B17: =Assumption!D12 -> 0 | C17: =B17*(1+$N$36) -> 0 | D17: =C17*(1+$N$36) -> 0 | E17: =D17*(1+$N$36) -> 0 | F17: =E17*(1+$N$36) -> 0 | G17: =F17*(1+$N$36) -> 0 | H17: =G17*(1+$N$36) -> 0 | I17: =H17*(1+$N$36) -> 0 | J17: =I17*(1+$N$36) -> 0 | ... L17: =K17*(1+$N$36) -> 0
A18: Rent Increase (%) | C18: =(C17-B17)/C17 -> #DIV/0! | D18: =(D17-C17)/D17 -> #DIV/0! | E18: =(E17-D17)/E17 -> #DIV/0! | F18: =(F17-E17)/F17 -> #DIV/0! | G18: =(G17-F17)/G17 -> #DIV/0! | H18: =(H17-G17)/H17 -> #DIV/0! | I18: =(I17-H17)/I17 -> #DIV/0! | J18: =(J17-I17)/J17 -> #DIV/0! | ... L18: =(L17-K17)/L17 -> #DIV/0!
A20: Occupied SFR | B20: =Assumption!B14 -> 0 | C20: =MIN($O20,B20+$P20) -> 0 | D20: =MIN($O20,C20+$P20) -> 0 | E20: =MIN($O20,D20+$P20) -> 0 | F20: =MIN($O20,E20+$P20) -> 0 | G20: =MIN($O20,F20+$P20) -> 0 | H20: =MIN($O20,G20+$P20) -> 0 | I20: =MIN($O20,H20+$P20) -> 0 | J20: =MIN($O20,I20+$P20) -> 0 | ... L20: =MIN($O20,K20+$P20) -> 0 | N20: =O20-B20 -> 0 | O20: =Assumption!B14+Assumption!B15 -> 0 | P20: 1
A21: Occupancy | B21: =B20/SUM(Assumption!$B$14:$B$15) -> #DIV/0! | C21: =C20/SUM(Assumption!$B$14:$B$15) -> #DIV/0! | D21: =D20/SUM(Assumption!$B$14:$B$15) -> #DIV/0! | E21: =E20/SUM(Assumption!$B$14:$B$15) -> #DIV/0! | F21: =F20/SUM(Assumption!$B$14:$B$15) -> #DIV/0! | G21: =G20/SUM(Assumption!$B$14:$B$15) -> #DIV/0! | H21: =H20/SUM(Assumption!$B$14:$B$15) -> #DIV/0! | I21: =I20/SUM(Assumption!$B$14:$B$15) -> #DIV/0! | ... L21: =L20/SUM(Assumption!$B$14:$B$15) -> #DIV/0!
A22: Average Rent | B22: =Assumption!D14 -> 0 | C22: =B22*(1+$N$37) -> 0 | D22: =C22*(1+$N$37) -> 0 | E22: =D22*(1+$N$37) -> 0 | F22: =E22*(1+$N$37) -> 0 | G22: =F22*(1+$N$37) -> 0 | H22: =G22*(1+$N$37) -> 0 | I22: =H22*(1+$N$37) -> 0 | J22: =I22*(1+$N$37) -> 0 | ... L22: =K22*(1+$N$37) -> 0
A23: Rent Increase (%) | C23: =(C22-B22)/C22 -> #DIV/0! | D23: =(D22-C22)/D22 -> #DIV/0! | E23: =(E22-D22)/E22 -> #DIV/0! | F23: =(F22-E22)/F22 -> #DIV/0! | G23: =(G22-F22)/G22 -> #DIV/0! | H23: =(H22-G22)/H22 -> #DIV/0! | I23: =(I22-H22)/I22 -> #DIV/0! | J23: =(J22-I22)/J22 -> #DIV/0! | ... L23: =(L22-K22)/L22 -> #DIV/0!
A25: Occupied SFH | B25: =Assumption!B16 -> 0 | C25: =MIN($O25,B25+$P25) -> 0 | D25: =MIN($O25,C25+$P25) -> 0 | E25: =MIN($O25,D25+$P25) -> 0 | F25: =MIN($O25,E25+$P25) -> 0 | G25: =MIN($O25,F25+$P25) -> 0 | H25: =MIN($O25,G25+$P25) -> 0 | I25: =MIN($O25,H25+$P25) -> 0 | J25: =MIN($O25,I25+$P25) -> 0 | ... L25: =MIN($O25,K25+$P25) -> 0 | N25: =O25-B25 -> 0 | O25: =Assumption!B16+Assumption!B17 -> 0 | P25: 1
A26: Occupancy | B26: =B25/SUM(Assumption!$B$16:$B$17) -> #DIV/0! | C26: =C25/SUM(Assumption!$B$16:$B$17) -> #DIV/0! | D26: =D25/SUM(Assumption!$B$16:$B$17) -> #DIV/0! | E26: =E25/SUM(Assumption!$B$16:$B$17) -> #DIV/0! | F26: =F25/SUM(Assumption!$B$16:$B$17) -> #DIV/0! | G26: =G25/SUM(Assumption!$B$16:$B$17) -> #DIV/0! | H26: =H25/SUM(Assumption!$B$16:$B$17) -> #DIV/0! | I26: =I25/SUM(Assumption!$B$16:$B$17) -> #DIV/0! | ... L26: =L25/SUM(Assumption!$B$16:$B$17) -> #DIV/0!
A27: Average Rent | B27: =Assumption!D16 -> 0 | C27: =B27*(1+$N$38) -> 0 | D27: =C27*(1+$N$38) -> 0 | E27: =D27*(1+$N$38) -> 0 | F27: =E27*(1+$N$38) -> 0 | G27: =F27*(1+$N$38) -> 0 | H27: =G27*(1+$N$38) -> 0 | I27: =H27*(1+$N$38) -> 0 | J27: =I27*(1+$N$38) -> 0 | ... L27: =K27*(1+$N$38) -> 0
A28: Rent Increase (%) | C28: =(C27-B27)/C27 -> #DIV/0! | D28: =(D27-C27)/D27 -> #DIV/0! | E28: =(E27-D27)/E27 -> #DIV/0! | F28: =(F27-E27)/F27 -> #DIV/0! | G28: =(G27-F27)/G27 -> #DIV/0! | H28: =(H27-G27)/H27 -> #DIV/0! | I28: =(I27-H27)/I27 -> #DIV/0! | J28: =(J27-I27)/J27 -> #DIV/0! | ... L28: =(L27-K27)/L27 -> #DIV/0!
A30: Total Occupied Units | B30: =B5+B10+B15+B20+B25 -> 46 | C30: =C5+C10+C15+C20+C25 -> 48 | D30: =D5+D10+D15+D20+D25 -> 50 | E30: =E5+E10+E15+E20+E25 -> 52 | F30: =F5+F10+F15+F20+F25 -> 54 | G30: =G5+G10+G15+G20+G25 -> 56 | H30: =H5+H10+H15+H20+H25 -> 58 | I30: =I5+I10+I15+I20+I25 -> 60 | ... L30: =L5+L10+L15+L20+L25 -> 66 | N30: =SUM(N5:N25) -> 23 | O30: =SUM(O5:O25) -> 69
A32: SECTION 2: REVENUE - Gross Potential less Vacancy (Base Year = actual occupancy)
A33: Revenue Head | B33: Base Year (Actual) | C33: Year 1 Revenue | D33: Year 2 Revenue | E33: Year 3 Revenue | F33: Year 4 Revenue | G33: Year 5 Revenue | H33: Year 6 Revenue | I33: Year 7 Revenue | J33: Year 8 Revenue | K33: Year 9 Revenue | L33: Year 10 Revenue | N33: Growth % (per head)
A34: Lot Rent | B34: =B5*B7*12 -> 148500 | C34: =B34*(1+$N34) -> 155925 | D34: =C34*(1+$N34) -> 163721.25 | E34: =D34*(1+$N34) -> 171907.31 | F34: =E34*(1+$N34) -> 180502.68 | G34: =F34*(1+$N34) -> 189527.81 | H34: =G34*(1+$N34) -> 199004.2 | I34: =H34*(1+$N34) -> 208954.41 | J34: =I34*(1+$N34) -> 219402.13 | ... L34: =K34*(1+$N34) -> 241890.85 | N34: 0.05
A35: Office Rent | B35: =$O10*Assumption!$D$10*12 -> 6000 | C35: =B35*(1+$N35) -> 6300 | D35: =C35*(1+$N35) -> 6615 | E35: =D35*(1+$N35) -> 6945.75 | F35: =E35*(1+$N35) -> 7293.0375 | G35: =F35*(1+$N35) -> 7657.6894 | H35: =G35*(1+$N35) -> 8040.5738 | I35: =H35*(1+$N35) -> 8442.6025 | J35: =I35*(1+$N35) -> 8864.7327 | ... L35: =K35*(1+$N35) -> 9773.3678 | N35: 0.05
A36: Studio Rent | B36: =$O15*Assumption!$D$12*12 -> 0 | C36: =B36*(1+$N36) -> 0 | D36: =C36*(1+$N36) -> 0 | E36: =D36*(1+$N36) -> 0 | F36: =E36*(1+$N36) -> 0 | G36: =F36*(1+$N36) -> 0 | H36: =G36*(1+$N36) -> 0 | I36: =H36*(1+$N36) -> 0 | J36: =I36*(1+$N36) -> 0 | ... L36: =K36*(1+$N36) -> 0 | N36: 0.05
A37: SFR Rent | B37: =$O20*Assumption!$D$14*12 -> 0 | C37: =B37*(1+$N37) -> 0 | D37: =C37*(1+$N37) -> 0 | E37: =D37*(1+$N37) -> 0 | F37: =E37*(1+$N37) -> 0 | G37: =F37*(1+$N37) -> 0 | H37: =G37*(1+$N37) -> 0 | I37: =H37*(1+$N37) -> 0 | J37: =I37*(1+$N37) -> 0 | ... L37: =K37*(1+$N37) -> 0 | N37: 0.05
A38: SFH Rent | B38: =$O25*Assumption!$D$16*12 -> 0 | C38: =B38*(1+$N38) -> 0 | D38: =C38*(1+$N38) -> 0 | E38: =D38*(1+$N38) -> 0 | F38: =E38*(1+$N38) -> 0 | G38: =F38*(1+$N38) -> 0 | H38: =G38*(1+$N38) -> 0 | I38: =H38*(1+$N38) -> 0 | J38: =I38*(1+$N38) -> 0 | ... L38: =K38*(1+$N38) -> 0 | N38: 0.05
A39: Less: Vacancy Loss | B39: =(((B5-$O$5)*B7)+((B10-$O$10)*B12))+((B15-$O$15)*B17)+((B20-$O$20)*B22)+((B25-$O$25)*B27) -> -6325 | C39: =(((C5-$O$5)*C7)+((C10-$O$10)*C12))+((C15-$O$15)*C17)+((C20-$O$20)*C22)+((C25-$O$25)*C27) -> -6063.75 | D39: =(((D5-$O$5)*D7)+((D10-$O$10)*D12))+((D15-$O$15)*D17)+((D20-$O$20)*D22)+((D25-$O$25)*D27) -> -5760.5625 | E39: =(((E5-$O$5)*E7)+((E10-$O$10)*E12))+((E15-$O$15)*E17)+((E20-$O$20)*E22)+((E25-$O$25)*E27) -> -5411.8969 | F39: =(((F5-$O$5)*F7)+((F10-$O$10)*F12))+((F15-$O$15)*F17)+((F20-$O$20)*F22)+((F25-$O$25)*F27) -> -5013.9633 | G39: =(((G5-$O$5)*G7)+((G10-$O$10)*G12))+((G15-$O$15)*G17)+((G20-$O$20)*G22)+((G25-$O$25)*G27) -> -4562.7066 | H39: =(((H5-$O$5)*H7)+((H10-$O$10)*H12))+((H15-$O$15)*H17)+((H20-$O$20)*H22)+((H25-$O$25)*H27) -> -4053.7893 | I39: =(((I5-$O$5)*I7)+((I10-$O$10)*I12))+((I15-$O$15)*I17)+((I20-$O$20)*I22)+((I25-$O$25)*I27) -> -3482.5735 | ... L39: =(((L5-$O$5)*L7)+((L10-$O$10)*L12))+((L15-$O$15)*L17)+((L20-$O$20)*L22)+((L25-$O$25)*L27) -> -1343.8381 | N39: Vacancy = vacant units / total units x potential rent, by head
A40: Less: Non-Cash Rent (enter as negative) | B40: 0 | C40: 0 | D40: 0 | E40: 0 | F40: 0 | G40: 0 | H40: 0 | I40: 0 | J40: 0 | K40: 0 | L40: 0
A41: Less: Concessions / Free Rent (enter as negative) | B41: 0 | C41: 0 | D41: 0 | E41: 0 | F41: 0 | G41: 0 | H41: 0 | I41: 0 | J41: 0 | K41: 0 | L41: 0
A42: Utility Recapture | B42: 13655 | C42: =C53*$O$42 -> 14064.65 | D42: =D53*$O$42 -> 14486.59 | E42: =E53*$O$42 -> 14921.187 | F42: =F53*$O$42 -> 15368.823 | G42: =G53*$O$42 -> 15829.887 | H42: =H53*$O$42 -> 16304.784 | I42: =I53*$O$42 -> 16793.928 | J42: =J53*$O$42 -> 17297.745 | ... L42: =L53*$O$42 -> 18351.178 | N42: Recapture Rate | O42: =B42/B53 -> 0.9756359
A43: Less: Bad Debt | B43: =-$N$43*(SUM(B34:B38)+B39+B40+B41) -> -2963.5 | C43: =-$N$43*(SUM(C34:C38)+C39+C40+C41) -> -3123.225 | D43: =-$N$43*(SUM(D34:D38)+D39+D40+D41) -> -3291.5138 | E43: =-$N$43*(SUM(E34:E38)+E39+E40+E41) -> -3468.8233 | F43: =-$N$43*(SUM(F34:F38)+F39+F40+F41) -> -3655.635 | G43: =-$N$43*(SUM(G34:G38)+G39+G40+G41) -> -3852.4559 | H43: =-$N$43*(SUM(H34:H38)+H39+H40+H41) -> -4059.8197 | I43: =-$N$43*(SUM(I34:I38)+I39+I40+I41) -> -4278.2888 | ... L43: =-$N$43*(SUM(L34:L38)+L39+L40+L41) -> -5006.4076 | N43: 0.02 | O43: <- bad debt % of effective rent
A44: Total Revenue | B44: =SUM(B34:B43) -> 158866.5 | C44: =SUM(C34:C43) -> 167102.67 | D44: =SUM(D34:D43) -> 175770.76 | E44: =SUM(E34:E43) -> 184893.53 | F44: =SUM(F34:F43) -> 194494.94 | G44: =SUM(G34:G43) -> 204600.23 | H44: =SUM(H34:H43) -> 215235.95 | I44: =SUM(I34:I43) -> 226430.08 | ... L44: =SUM(L34:L43) -> 263665.15
A46: SECTION 3: EXPENSES
A47: Expense Head | B47: Base Year | C47: Year 1 | D47: Year 2 | E47: Year 3 | F47: Year 4 | G47: Year 5 | H47: Year 6 | I47: Year 7 | J47: Year 8 | K47: Year 9 | L47: Year 10 | N47: Growth % | O47: Rate A | P47: Rate B / Count | Q47: Est. Base Year
A48: Property Tax | B48: 4764 | C48: =B48*(1+$N48) -> 4906.92 | D48: =C48*(1+$N48) -> 5054.1276 | E48: =D48*(1+$N48) -> 5205.7514 | F48: =E48*(1+$N48) -> 5361.924 | G48: =F48*(1+$N48) -> 5522.7817 | H48: =G48*(1+$N48) -> 5688.4651 | I48: =H48*(1+$N48) -> 5859.1191 | J48: =I48*(1+$N48) -> 6034.8927 | ... L48: =K48*(1+$N48) -> 6402.4176 | N48: 0.03
...

Sheet POH 
A1: Land - Lot Only (Major Income)
A2: Occupancy ramps by Lease-Up/Yr (col P) up to Total Units (col O). Revenue = potential less vacancy less bad debt.
A3: Head / Category | B3: 2018 | C3: Year 1 Occupied | D3: Year 2 Occupied | E3: Year 3 Occupied | F3: Year 4 Occupied | G3: Year 5 Occupied | H3: Year 6 Occupied | I3: Year 7 Occupied | J3: Year 8 Occupied | K3: Year 9 Occupied | L3: Year 10 Occupied | N3: Base Year Vacant | O3: Total Units | P3: Lease-Up / Yr
A5: Occupied POH | B5: =Assumption!B8 -> 8 | C5: =MIN($O5,B5+$P5) -> 10 | D5: =MIN($O5,C5+$P5) -> 12 | E5: =MIN($O5,D5+$P5) -> 14 | F5: =MIN($O5,E5+$P5) -> 16 | G5: =MIN($O5,F5+$P5) -> 17 | H5: =MIN($O5,G5+$P5) -> 17 | I5: =MIN($O5,H5+$P5) -> 17 | J5: =MIN($O5,I5+$P5) -> 17 | ... L5: =MIN($O5,K5+$P5) -> 17 | N5: =O5-B5 -> 9 | O5: =SUM(Assumption!B8:B9) -> 17 | P5: 2
A6: Occupancy | B6: =B5/SUM(Assumption!$B$8:$B$9) -> 0.47058824 | C6: =C5/SUM(Assumption!$B$8:$B$9) -> 0.58823529 | D6: =D5/SUM(Assumption!$B$8:$B$9) -> 0.70588235 | E6: =E5/SUM(Assumption!$B$8:$B$9) -> 0.82352941 | F6: =F5/SUM(Assumption!$B$8:$B$9) -> 0.94117647 | G6: =G5/SUM(Assumption!$B$8:$B$9) -> 1 | H6: =H5/SUM(Assumption!$B$8:$B$9) -> 1 | I6: =I5/SUM(Assumption!$B$8:$B$9) -> 1 | ... L6: =L5/SUM(Assumption!$B$8:$B$9) -> 1
A7: Average POH Rent | B7: =Assumption!D8 -> 228.125 | C7: =B7*(1+$N$19) -> 239.53125 | D7: =C7*(1+$N$19) -> 251.50781 | E7: =D7*(1+$N$19) -> 264.0832 | F7: =E7*(1+$N$19) -> 277.28736 | G7: =F7*(1+$N$19) -> 291.15173 | H7: =G7*(1+$N$19) -> 305.70932 | I7: =H7*(1+$N$19) -> 320.99478 | J7: =I7*(1+$N$19) -> 337.04452 | ... L7: =K7*(1+$N$19) -> 371.59159
A8: Rent Increase (%) | C8: =(C7-B7)/C7 -> 0.047619048 | D8: =(D7-C7)/D7 -> 0.047619048 | E8: =(E7-D7)/E7 -> 0.047619048 | F8: =(F7-E7)/F7 -> 0.047619048 | G8: =(G7-F7)/G7 -> 0.047619048 | H8: =(H7-G7)/H7 -> 0.047619048 | I8: =(I7-H7)/I7 -> 0.047619048 | J8: =(J7-I7)/J7 -> 0.047619048 | ... L8: =(L7-K7)/L7 -> 0.047619048
A10: Occupied RV | B10: =Assumption!B18 -> 0 | C10: =MIN($O10,B10+$P10) -> 0 | D10: =MIN($O10,C10+$P10) -> 0 | E10: =MIN($O10,D10+$P10) -> 0 | F10: =MIN($O10,E10+$P10) -> 0 | G10: =MIN($O10,F10+$P10) -> 0 | H10: =MIN($O10,G10+$P10) -> 0 | I10: =MIN($O10,H10+$P10) -> 0 | J10: =MIN($O10,I10+$P10) -> 0 | ... L10: =MIN($O10,K10+$P10) -> 0 | N10: =O10-B10 -> 0 | O10: =Assumption!B18+Assumption!B19 -> 0 | P10: 0
A11: Occupancy | B11: =B10/SUM(Assumption!$B$18:$B$19) -> #DIV/0! | C11: =C10/SUM(Assumption!$B$18:$B$19) -> #DIV/0! | D11: =D10/SUM(Assumption!$B$18:$B$19) -> #DIV/0! | E11: =E10/SUM(Assumption!$B$18:$B$19) -> #DIV/0! | F11: =F10/SUM(Assumption!$B$18:$B$19) -> #DIV/0! | G11: =G10/SUM(Assumption!$B$18:$B$19) -> #DIV/0! | H11: =H10/SUM(Assumption!$B$18:$B$19) -> #DIV/0! | I11: =I10/SUM(Assumption!$B$18:$B$19) -> #DIV/0! | ... L11: =L10/SUM(Assumption!$B$18:$B$19) -> #DIV/0!
A12: Average RV Rent | B12: =Assumption!D18 -> 0 | C12: =B12*(1+$N$20) -> 0 | D12: =C12*(1+$N$20) -> 0 | E12: =D12*(1+$N$20) -> 0 | F12: =E12*(1+$N$20) -> 0 | G12: =F12*(1+$N$20) -> 0 | H12: =G12*(1+$N$20) -> 0 | I12: =H12*(1+$N$20) -> 0 | J12: =I12*(1+$N$20) -> 0 | ... L12: =K12*(1+$N$20) -> 0
A13: Rent Increase (%) | C13: =(C12-B12)/C12 -> #DIV/0! | D13: =(D12-C12)/D12 -> #DIV/0! | E13: =(E12-D12)/E12 -> #DIV/0! | F13: =(F12-E12)/F12 -> #DIV/0! | G13: =(G12-F12)/G12 -> #DIV/0! | H13: =(H12-G12)/H12 -> #DIV/0! | I13: =(I12-H12)/I12 -> #DIV/0! | J13: =(J12-I12)/J12 -> #DIV/0! | ... L13: =(L12-K12)/L12 -> #DIV/0!
A15: Total Occupied Units | B15: =B5+B10 -> 8 | C15: =C5+C10 -> 10 | D15: =D5+D10 -> 12 | E15: =E5+E10 -> 14 | F15: =F5+F10 -> 16 | G15: =G5+G10 -> 17 | H15: =H5+H10 -> 17 | I15: =I5+I10 -> 17 | ... L15: =L5+L10 -> 17 | N15: =SUM(N5:N13) -> 9 | O15: =SUM(O5:O13) -> 17
A17: SECTION 2: REVENUE - Gross Potential less Vacancy (Base Year = actual occupancy)
A18: Revenue Head | B18: Base Year (Actual) | C18: Year 1 Revenue | D18: Year 2 Revenue | E18: Year 3 Revenue | F18: Year 4 Revenue | G18: Year 5 Revenue | H18: Year 6 Revenue | I18: Year 7 Revenue | J18: Year 8 Revenue | K18: Year 9 Revenue | L18: Year 10 Revenue | N18: Growth % (per head)
A19: POH Rent | B19: =B5*B7*12 -> 21900 | C19: =B19*(1+$N19) -> 22995 | D19: =C19*(1+$N19) -> 24144.75 | E19: =D19*(1+$N19) -> 25351.987 | F19: =E19*(1+$N19) -> 26619.587 | G19: =F19*(1+$N19) -> 27950.566 | H19: =G19*(1+$N19) -> 29348.095 | I19: =H19*(1+$N19) -> 30815.499 | J19: =I19*(1+$N19) -> 32356.274 | ... L19: =K19*(1+$N19) -> 35672.792 | N19: 0.05
A20: RV Rent | B20: =B10*B12*12 -> 0 | C20: =C10*C12*12 -> 0 | D20: =D10*D12*12 -> 0 | E20: =E10*E12*12 -> 0 | F20: =F10*F12*12 -> 0 | G20: =G10*G12*12 -> 0 | H20: =H10*H12*12 -> 0 | I20: =I10*I12*12 -> 0 | ... L20: =L10*L12*12 -> 0 | N20: 0.05
A21: RTO | B21: =RTO!F33*12 -> 88944 | C21: =RTO!G33 -> 88944 | D21: =RTO!H33 -> 88944 | E21: =RTO!I33 -> 88944 | F21: =RTO!J33 -> 88944 | G21: =RTO!K33 -> 88944 | H21: =RTO!L33 -> 88944 | I21: =RTO!M33 -> 88944 | J21: =RTO!N33 -> 88944 | ... L21: =RTO!P33 -> 88944 | N21: 0.05
A22: Less: Vacancy Loss | B22: =-((($O$5-B5)*B7)+(($O$10-B10)*B12)) -> -2053.125 | C22: =-((($O$5-C5)*C7)+(($O$10-C10)*C12)) -> -1676.7188 | D22: =-((($O$5-D5)*D7)+(($O$10-D10)*D12)) -> -1257.5391 | E22: =-((($O$5-E5)*E7)+(($O$10-E10)*E12)) -> -792.24961 | F22: =-((($O$5-F5)*F7)+(($O$10-F10)*F12)) -> -277.28736 | G22: =-((($O$5-G5)*G7)+(($O$10-G10)*G12)) -> 0 | H22: =-((($O$5-H5)*H7)+(($O$10-H10)*H12)) -> 0 | I22: =-((($O$5-I5)*I7)+(($O$10-I10)*I12)) -> 0 | ... L22: =-((($O$5-L5)*L7)+(($O$10-L10)*L12)) -> 0 | N22: Vacancy = vacant units / total units x potential rent, by head
A23: Less: Non-Cash Rent (enter as negative) | B23: 0 | C23: 0 | D23: 0 | E23: 0 | F23: 0 | G23: 0 | H23: 0 | I23: 0 | J23: 0 | K23: 0 | L23: 0
A24: Less: Concessions / Free Rent (enter as negative) | B24: 0 | C24: 0 | D24: 0 | E24: 0 | F24: 0 | G24: 0 | H24: 0 | I24: 0 | J24: 0 | K24: 0 | L24: 0
A25: Total Revenue | B25: =SUM(B19:B24) -> 108790.88 | C25: =SUM(C19:C24) -> 110262.28 | D25: =SUM(D19:D24) -> 111831.21 | E25: =SUM(E19:E24) -> 113503.74 | F25: =SUM(F19:F24) -> 115286.3 | G25: =SUM(G19:G24) -> 116894.57 | H25: =SUM(H19:H24) -> 118292.09 | I25: =SUM(I19:I24) -> 119759.5 | ... L25: =SUM(L19:L24) -> 124616.79
A27: SECTION 3: EXPENSES
A28: Expense Head | B28: Base Year | C28: Year 1 | D28: Year 2 | E28: Year 3 | F28: Year 4 | G28: Year 5 | H28: Year 6 | I28: Year 7 | J28: Year 8 | K28: Year 9 | L28: Year 10 | N28: Growth % | O28: Rate A | P28: Rate B / Count | Q28: Est. Base Year
A29: POH Repairs | B29: 4764 | C29: =B29*(1+$N29) -> 4906.92 | D29: =C29*(1+$N29) -> 5054.1276 | E29: =D29*(1+$N29) -> 5205.7514 | F29: =E29*(1+$N29) -> 5361.924 | G29: =F29*(1+$N29) -> 5522.7817 | H29: =G29*(1+$N29) -> 5688.4651 | I29: =H29*(1+$N29) -> 5859.1191 | J29: =I29*(1+$N29) -> 6034.8927 | ... L29: =K29*(1+$N29) -> 6402.4176 | N29: 0.03
A30: POH Insurance | B30: 4619 | C30: =B30*(1+$N30) -> 4757.57 | D30: =C30*(1+$N30) -> 4900.2971 | E30: =D30*(1+$N30) -> 5047.306 | F30: =E30*(1+$N30) -> 5198.7252 | G30: =F30*(1+$N30) -> 5354.6869 | H30: =G30*(1+$N30) -> 5515.3276 | I30: =H30*(1+$N30) -> 5680.7874 | J30: =I30*(1+$N30) -> 5851.211 | ... L30: =K30*(1+$N30) -> 6207.5498 | N30: 0.03
A31: POH Expense | B31: 41200 | C31: =B31*(1+$N31) -> 42436 | D31: =C31*(1+$N31) -> 43709.08 | E31: =D31*(1+$N31) -> 45020.352 | F31: =E31*(1+$N31) -> 46370.963 | G31: =F31*(1+$N31) -> 47762.092 | H31: =G31*(1+$N31) -> 49194.955 | I31: =H31*(1+$N31) -> 50670.803 | J31: =I31*(1+$N31) -> 52190.927 | ... L31: =K31*(1+$N31) -> 55369.355 | N31: 0.03
A32: Other POH Expenses | B32: 0 | C32: =B32*(1+$N32) -> 0 | D32: =C32*(1+$N32) -> 0 | E32: =D32*(1+$N32) -> 0 | F32: =E32*(1+$N32) -> 0 | G32: =F32*(1+$N32) -> 0 | H32: =G32*(1+$N32) -> 0 | I32: =H32*(1+$N32) -> 0 | J32: =I32*(1+$N32) -> 0 | ... L32: =K32*(1+$N32) -> 0 | N32: 0.03 | O32: 15 | P32: =B15 -> 8 | Q32: =O32*P32*12 -> 1440 | R32: If actual known, type it in column B. Otherwise B = Q ($/unit/mo x occupied units x 12).
A33: Electricity | N33: 0.03
A34: Total Expenses | B34: =SUM(B29:B33) -> 50583 | C34: =SUM(C29:C33) -> 52100.49 | D34: =SUM(D29:D33) -> 53663.505 | E34: =SUM(E29:E33) -> 55273.41 | F34: =SUM(F29:F33) -> 56931.612 | G34: =SUM(G29:G33) -> 58639.561 | H34: =SUM(H29:H33) -> 60398.747 | I34: =SUM(I29:I33) -> 62210.71 | ... L34: =SUM(L29:L33) -> 67979.322
A35: NOI | B35: =B25-B34 -> 58207.875 | C35: =C25-C34 -> 58161.791 | D35: =D25-D34 -> 58167.706 | E35: =E25-E34 -> 58230.328 | F35: =F25-F34 -> 58354.687 | G35: =G25-G34 -> 58255.006 | H35: =H25-H34 -> 57893.347 | I35: =I25-I34 -> 57548.79 | ... L35: =L25-L34 -> 56637.47
A36: Expense Ratio | B36: =B34/B25 -> 0.46495628 | C36: =C34/C25 -> 0.47251417 | D36: =D34/D25 -> 0.47986161 | E36: =E34/E25 -> 0.48697436 | F36: =F34/F25 -> 0.49382808 | G36: =G34/G25 -> 0.50164488 | H36: =H34/H25 -> 0.51058989 | I36: =I34/I25 -> 0.51946368 | ... L36: =L34/L25 -> 0.54550692

Sheet Cash Flow Model
A1: Acquisition Model - Consolidated (Land + POH)
A2: Land (Major) + POH (Minor) -> Total NOI. Price, debt terms and hold period come from the BOV sheet.
A4: Assumptions | D4: Deal Controls (from BOV sheet)
A5: Total Value = Purchase Price (from BOV) | B5: ='BOV '!B7 -> 1735250.3 | D5: Hold Period (Years) | E5: ='BOV '!B39 -> 10
A6: LTV (from BOV) | B6: ='BOV '!B20 -> 0.7 | D6: Purchase Price Used | E6: =B5 -> 1735250.3
A7: Interest Rate = SOFR + Spread (from BOV) | B7: ='BOV '!B22 -> 0.07023 | D7: Loan Amount | E7: =E6*B6 -> 1214675.2
A8: Amort Years (from BOV) | B8: ='BOV '!B36 -> 30 | D8: Equity Invested | E8: =E6-E7 -> 520575.08
A9: Exit Cap | B9: 0.06
A10: Selling Costs % | B10: 0.02
A12: Line Item | B12: Base Year | C12: Year 1 | D12: Year 2 | E12: Year 3 | F12: Year 4 | G12: Year 5 | H12: Year 6 | I12: Year 7 | J12: Year 8 | K12: Year 9 | L12: Year 10
A13: Land Total Revenue | B13: =Land!B44 -> 158866.5 | C13: =Land!C44 -> 167102.67 | D13: =Land!D44 -> 175770.76 | E13: =Land!E44 -> 184893.53 | F13: =Land!F44 -> 194494.94 | G13: =Land!G44 -> 204600.23 | H13: =Land!H44 -> 215235.95 | I13: =Land!I44 -> 226430.08 | ... L13: =Land!L44 -> 263665.15
A14: POH Total Revenue | B14: ='POH '!B25 -> 108790.88 | C14: ='POH '!C25 -> 110262.28 | D14: ='POH '!D25 -> 111831.21 | E14: ='POH '!E25 -> 113503.74 | F14: ='POH '!F25 -> 115286.3 | G14: ='POH '!G25 -> 116894.57 | H14: ='POH '!H25 -> 118292.09 | I14: ='POH '!I25 -> 119759.5 | ... L14: ='POH '!L25 -> 124616.79
A15: Total Revenue | B15: =B13+B14 -> 267657.38 | C15: =C13+C14 -> 277364.96 | D15: =D13+D14 -> 287601.97 | E15: =E13+E14 -> 298397.27 | F15: =F13+F14 -> 309781.24 | G15: =G13+G14 -> 321494.79 | H15: =H13+H14 -> 333528.05 | I15: =I13+I14 -> 346189.58 | ... L15: =L13+L14 -> 388281.94
A16: Land Total Expenses | B16: =Land!B63 -> 48162 | C16: =Land!C63 -> 43945.754 | D16: =Land!D63 -> 45446.877 | E16: =Land!E63 -> 47002.765 | F16: =Land!F63 -> 48615.578 | G16: =Land!G63 -> 50287.568 | H16: =Land!H63 -> 52021.081 | I16: =Land!I63 -> 53818.566 | ... L16: =Land!L63 -> 59620.944
A17: POH Total Expenses | B17: ='POH '!B34 -> 50583 | C17: ='POH '!C34 -> 52100.49 | D17: ='POH '!D34 -> 53663.505 | E17: ='POH '!E34 -> 55273.41 | F17: ='POH '!F34 -> 56931.612 | G17: ='POH '!G34 -> 58639.561 | H17: ='POH '!H34 -> 60398.747 | I17: ='POH '!I34 -> 62210.71 | ... L17: ='POH '!L34 -> 67979.322
A18: Total Expenses | B18: =B16+B17 -> 98745 | C18: =C16+C17 -> 96046.244 | D18: =D16+D17 -> 99110.381 | E18: =E16+E17 -> 102276.18 | F18: =F16+F17 -> 105547.19 | G18: =G16+G17 -> 108927.13 | H18: =H16+H17 -> 112419.83 | I18: =I16+I17 -> 116029.28 | ... L18: =L16+L17 -> 127600.27
A19: NOI (Land + POH) | B19: =B15-B18 -> 168912.38 | C19: =C15-C18 -> 181318.71 | D19: =D15-D18 -> 188491.59 | E19: =E15-E18 -> 196121.09 | F19: =F15-F18 -> 204234.05 | G19: =G15-G18 -> 212567.66 | H19: =H15-H18 -> 221108.22 | I19: =I15-I18 -> 230160.3 | ... L19: =L15-L18 -> 260681.68
A20: Debt Service & Levered
A21: Debt Service (from Debt Sheet) | C21: ='Loan Amortization '!B11 -> 98112.565 | D21: ='Loan Amortization '!C11 -> 98112.565 | E21: ='Loan Amortization '!D11 -> 98112.565 | F21: ='Loan Amortization '!E11 -> 98112.565 | G21: ='Loan Amortization '!F11 -> 98112.565 | H21: ='Loan Amortization '!G11 -> 98112.565 | I21: ='Loan Amortization '!H11 -> 98112.565 | J21: ='Loan Amortization '!I11 -> 98112.565 | ... L21: ='Loan Amortization '!K11 -> 98112.565
A22: Interest | C22: ='Loan Amortization '!B12 -> 85306.638 | D22: ='Loan Amortization '!C12 -> 84407.278 | E22: ='Loan Amortization '!D12 -> 83444.756 | F22: ='Loan Amortization '!E12 -> 82414.635 | G22: ='Loan Amortization '!F12 -> 81312.17 | H22: ='Loan Amortization '!G12 -> 80132.278 | I22: ='Loan Amortization '!H12 -> 78869.523 | J22: ='Loan Amortization '!I12 -> 77518.084 | ... L22: ='Loan Amortization '!K12 -> 74523.806
A23: Principal | C23: ='Loan Amortization '!B13 -> 12805.927 | D23: ='Loan Amortization '!C13 -> 13705.287 | E23: ='Loan Amortization '!D13 -> 14667.809 | F23: ='Loan Amortization '!E13 -> 15697.929 | G23: ='Loan Amortization '!F13 -> 16800.395 | H23: ='Loan Amortization '!G13 -> 17980.287 | I23: ='Loan Amortization '!H13 -> 19243.042 | J23: ='Loan Amortization '!I13 -> 20594.481 | ... L23: ='Loan Amortization '!K13 -> 23588.759
A24: Levered Cash Flow (NOI - Debt Service) | C24: =C19-C21 -> 83206.148 | D24: =D19-D21 -> 90379.028 | E24: =E19-E21 -> 98008.527 | F24: =F19-F21 -> 106121.48 | G24: =G19-G21 -> 114455.1 | H24: =H19-H21 -> 122995.65 | I24: =I19-I21 -> 132047.74 | J24: =J19-J21 -> 141640.16 | ... L24: =L19-L21 -> 162569.11
A25: DSCR (NOI / Debt Service) | C25: =IF(C21=0,0,C19/C21) -> 1.8480682 | D25: =IF(D21=0,0,D19/D21) -> 1.9211769 | E25: =IF(E21=0,0,E19/E21) -> 1.9989396 | F25: =IF(F21=0,0,F19/F21) -> 2.0816299 | G25: =IF(G21=0,0,G19/G21) -> 2.1665692 | H25: =IF(H21=0,0,H19/H21) -> 2.2536178 | I25: =IF(I21=0,0,I19/I21) -> 2.34588 | J25: =IF(J21=0,0,J19/J21) -> 2.4436495 | ... L25: =IF(L21=0,0,L19/L21) -> 2.6569653
A26: Expense Ratio | B26: =B18/B15 -> 0.36892314 | C26: =C18/C15 -> 0.34628111 | D26: =D18/D15 -> 0.34460953 | E26: =E18/E15 -> 0.34275171 | F26: =F18/F15 -> 0.34071524 | G26: =G18/G15 -> 0.3388146 | H26: =H18/H15 -> 0.33706259 | I26: =I18/I15 -> 0.33516109 | ... L26: =L18/L15 -> 0.32862786
A28: Exit & Appreciation (sale at end of hold period)
A29: Hold Period (Years) | B29: =E5 -> 10
A30: Exit-Year NOI (trailing) | B30: =INDEX(C19:L19,B29) -> 260681.68
A31: Exit Value (NOI / Exit Cap) | B31: =B30/B9 -> 4344694.6
A32: Less: Selling Costs | B32: =B31*B10 -> 86893.893
A33: Less: Ending Loan Balance | B33: =INDEX('Loan Amortization '!B14:K14,B29) -> 1037550.4
A34: Net Sale Proceeds | B34: =B31-B32-B33 -> 3220250.3
A35: Appreciation (Exit Value - Purchase Price) | B35: =B31-E6 -> 2609444.4
A37: Cash Flow to Equity & Returns
A38: Year | B38: 0 | C38: 1 | D38: 2 | E38: 3 | F38: 4 | G38: 5 | H38: 6 | I38: 7 | J38: 8 | K38: 9 | L38: 10
A39: Levered Cash Flow (incl. sale in hold year) | B39: =-E8 -> -520575.08 | C39: =IF(C$38<=$B$29,C24,0)+IF(C$38=$B$29,$B$34,0) -> 83206.148 | D39: =IF(D$38<=$B$29,D24,0)+IF(D$38=$B$29,$B$34,0) -> 90379.028 | E39: =IF(E$38<=$B$29,E24,0)+IF(E$38=$B$29,$B$34,0) -> 98008.527 | F39: =IF(F$38<=$B$29,F24,0)+IF(F$38=$B$29,$B$34,0) -> 106121.48 | G39: =IF(G$38<=$B$29,G24,0)+IF(G$38=$B$29,$B$34,0) -> 114455.1 | H39: =IF(H$38<=$B$29,H24,0)+IF(H$38=$B$29,$B$34,0) -> 122995.65 | I39: =IF(I$38<=$B$29,I24,0)+IF(I$38=$B$29,$B$34,0) -> 132047.74 | J39: =IF(J$38<=$B$29,J24,0)+IF(J$38=$B$29,$B$34,0) -> 141640.16 | ... L39: =IF(L$38<=$B$29,L24,0)+IF(L$38=$B$29,$B$34,0) -> 3382819.4
A40: Unlevered Cash Flow (incl. sale in hold year) | B40: =-E6 -> -1735250.3 | C40: =IF(C$38<=$B$29,C19,0)+IF(C$38=$B$29,$B$31-$B$32,0) -> 181318.71 | D40: =IF(D$38<=$B$29,D19,0)+IF(D$38=$B$29,$B$31-$B$32,0) -> 188491.59 | E40: =IF(E$38<=$B$29,E19,0)+IF(E$38=$B$29,$B$31-$B$32,0) -> 196121.09 | F40: =IF(F$38<=$B$29,F19,0)+IF(F$38=$B$29,$B$31-$B$32,0) -> 204234.05 | G40: =IF(G$38<=$B$29,G19,0)+IF(G$38=$B$29,$B$31-$B$32,0) -> 212567.66 | H40: =IF(H$38<=$B$29,H19,0)+IF(H$38=$B$29,$B$31-$B$32,0) -> 221108.22 | I40: =IF(I$38<=$B$29,I19,0)+IF(I$38=$B$29,$B$31-$B$32,0) -> 230160.3 | J40: =IF(J$38<=$B$29,J19,0)+IF(J$38=$B$29,$B$31-$B$32,0) -> 239752.72 | ... L40: =IF(L$38<=$B$29,L19,0)+IF(L$38=$B$29,$B$31-$B$32,0) -> 4518482.4
A42: Levered IRR | B42: =IFERROR(IRR(B39:L39),IFERROR(IRR(B39:L39,-0.5),"n/a")) -> 0.31239317
A43: Unlevered IRR | B43: =IFERROR(IRR(B40:L40),IFERROR(IRR(B40:L40,-0.5),"n/a")) -> 0.18086651
A44: Equity Multiple | B44: =SUM(C39:L39)/E8 -> 8.4972883
A45: Cash-on-Cash (Year 1) | B45: =C24/E8 -> 0.15983506
...

Sheet IRR by Exit Year Analysis
A1: IRR - Returns by Exit Year
A2: What the deal returns if sold at the end of each year (1-10), using the Acquisition Model assumptions.
A4: Sale Year | B4: 1 | C4: 2 | D4: 3 | E4: 4 | F4: 5 | G4: 6 | H4: 7 | I4: 8 | J4: 9 | K4: 10
A5: Exit NOI (trailing) | B5: =INDEX('Cash Flow Model'!$C$19:$L$19,B$4) -> 181318.71 | C5: =INDEX('Cash Flow Model'!$C$19:$L$19,C$4) -> 188491.59 | D5: =INDEX('Cash Flow Model'!$C$19:$L$19,D$4) -> 196121.09 | E5: =INDEX('Cash Flow Model'!$C$19:$L$19,E$4) -> 204234.05 | F5: =INDEX('Cash Flow Model'!$C$19:$L$19,F$4) -> 212567.66 | G5: =INDEX('Cash Flow Model'!$C$19:$L$19,G$4) -> 221108.22 | H5: =INDEX('Cash Flow Model'!$C$19:$L$19,H$4) -> 230160.3 | I5: =INDEX('Cash Flow Model'!$C$19:$L$19,I$4) -> 239752.72 | ... K5: =INDEX('Cash Flow Model'!$C$19:$L$19,K$4) -> 260681.68
A6: Gross Exit Value | B6: =B5/'Cash Flow Model'!$B$9 -> 3021978.5 | C6: =C5/'Cash Flow Model'!$B$9 -> 3141526.5 | D6: =D5/'Cash Flow Model'!$B$9 -> 3268684.9 | E6: =E5/'Cash Flow Model'!$B$9 -> 3403900.8 | F6: =F5/'Cash Flow Model'!$B$9 -> 3542794.4 | G6: =G5/'Cash Flow Model'!$B$9 -> 3685137 | H6: =H5/'Cash Flow Model'!$B$9 -> 3836005.1 | I6: =I5/'Cash Flow Model'!$B$9 -> 3995878.7 | ... K6: =K5/'Cash Flow Model'!$B$9 -> 4344694.6
A7: Selling Costs | B7: =B6*'Cash Flow Model'!$B$10 -> 60439.571 | C7: =C6*'Cash Flow Model'!$B$10 -> 62830.531 | D7: =D6*'Cash Flow Model'!$B$10 -> 65373.697 | E7: =E6*'Cash Flow Model'!$B$10 -> 68078.016 | F7: =F6*'Cash Flow Model'!$B$10 -> 70855.888 | G7: =G6*'Cash Flow Model'!$B$10 -> 73702.739 | H7: =H6*'Cash Flow Model'!$B$10 -> 76720.101 | I7: =I6*'Cash Flow Model'!$B$10 -> 79917.574 | ... K7: =K6*'Cash Flow Model'!$B$10 -> 86893.893
A8: Ending Loan Balance | B8: =INDEX('Loan Amortization '!$B$14:$K$14,B$4) -> 1201869.3 | C8: =INDEX('Loan Amortization '!$B$14:$K$14,C$4) -> 1188164 | D8: =INDEX('Loan Amortization '!$B$14:$K$14,D$4) -> 1173496.2 | E8: =INDEX('Loan Amortization '!$B$14:$K$14,E$4) -> 1157798.2 | F8: =INDEX('Loan Amortization '!$B$14:$K$14,F$4) -> 1140997.8 | G8: =INDEX('Loan Amortization '!$B$14:$K$14,G$4) -> 1123017.6 | H8: =INDEX('Loan Amortization '!$B$14:$K$14,H$4) -> 1103774.5 | I8: =INDEX('Loan Amortization '!$B$14:$K$14,I$4) -> 1083180 | ... K8: =INDEX('Loan Amortization '!$B$14:$K$14,K$4) -> 1037550.4
A9: Net Sale Proceeds | B9: =B6-B7-B8 -> 1759669.7 | C9: =C6-C7-C8 -> 1890532 | D9: =D6-D7-D8 -> 2029815 | E9: =E6-E7-E8 -> 2178024.6 | F9: =F6-F7-F8 -> 2330940.7 | G9: =G6-G7-G8 -> 2488416.7 | H9: =H6-H7-H8 -> 2655510.5 | I9: =I6-I7-I8 -> 2832781.1 | ... K9: =K6-K7-K8 -> 3220250.3
A10: Levered Cash Flow in Sale Year | B10: =INDEX('Cash Flow Model'!$C$24:$L$24,B$4) -> 83206.148 | C10: =INDEX('Cash Flow Model'!$C$24:$L$24,C$4) -> 90379.028 | D10: =INDEX('Cash Flow Model'!$C$24:$L$24,D$4) -> 98008.527 | E10: =INDEX('Cash Flow Model'!$C$24:$L$24,E$4) -> 106121.48 | F10: =INDEX('Cash Flow Model'!$C$24:$L$24,F$4) -> 114455.1 | G10: =INDEX('Cash Flow Model'!$C$24:$L$24,G$4) -> 122995.65 | H10: =INDEX('Cash Flow Model'!$C$24:$L$24,H$4) -> 132047.74 | I10: =INDEX('Cash Flow Model'!$C$24:$L$24,I$4) -> 141640.16 | ... K10: =INDEX('Cash Flow Model'!$C$24:$L$24,K$4) -> 162569.11
A11: Total Cash Flow in Sale Year | B11: =B9+B10 -> 1842875.9 | C11: =C9+C10 -> 1980911.1 | D11: =D9+D10 -> 2127823.5 | E11: =E9+E10 -> 2284146.1 | F11: =F9+F10 -> 2445395.8 | G11: =G9+G10 -> 2611412.3 | H11: =H9+H10 -> 2787558.2 | I11: =I9+I10 -> 2974421.2 | ... K11: =K9+K10 -> 3382819.4
A12: Equity Invested | B12: ='Cash Flow Model'!$E$8 -> 520575.08 | C12: ='Cash Flow Model'!$E$8 -> 520575.08 | D12: ='Cash Flow Model'!$E$8 -> 520575.08 | E12: ='Cash Flow Model'!$E$8 -> 520575.08 | F12: ='Cash Flow Model'!$E$8 -> 520575.08 | G12: ='Cash Flow Model'!$E$8 -> 520575.08 | H12: ='Cash Flow Model'!$E$8 -> 520575.08 | I12: ='Cash Flow Model'!$E$8 -> 520575.08 | ... K12: ='Cash Flow Model'!$E$8 -> 520575.08
A13: Levered IRR | B13: =IFERROR(IRR($B19:$L19),IFERROR(IRR($B19:$L19,-0.5),"n/a")) -> 2.540077 | C13: =IFERROR(IRR($B20:$L20),IFERROR(IRR($B20:$L20,-0.5),"n/a")) -> 1.0322553 | D13: =IFERROR(IRR($B21:$L21),IFERROR(IRR($B21:$L21,-0.5),"n/a")) -> 0.69134222 | E13: =IFERROR(IRR($B22:$L22),IFERROR(IRR($B22:$L22,-0.5),"n/a")) -> 0.54380381 | F13: =IFERROR(IRR($B23:$L23),IFERROR(IRR($B23:$L23,-0.5),"n/a")) -> 0.46154208 | G13: =IFERROR(IRR($B24:$L24),IFERROR(IRR($B24:$L24,-0.5),"n/a")) -> 0.40918068 | H13: =IFERROR(IRR($B25:$L25),IFERROR(IRR($B25:$L25,-0.5),"n/a")) -> 0.3732893 | I13: =IFERROR(IRR($B26:$L26),IFERROR(IRR($B26:$L26,-0.5),"n/a")) -> 0.34727558 | J13: =IFERROR(IRR($B27:$L27),IFERROR(IRR($B27:$L27,-0.5),"n/a")) -> 0.3276499 | K13: =IFERROR(IRR($B28:$L28),IFERROR(IRR($B28:$L28,-0.5),"n/a")) -> 0.31239317
A14: Equity Multiple | B14: =SUM($C19:$L19)/B12 -> 3.540077 | C14: =SUM($C20:$L20)/C12 -> 3.9650711 | D14: =SUM($C21:$L21)/D12 -> 4.4208968 | E14: =SUM($C22:$L22)/E12 -> 4.9094547 | F14: =SUM($C23:$L23)/F12 -> 5.4230621 | G14: =SUM($C24:$L24)/G12 -> 5.9618348 | H14: =SUM($C25:$L25)/H12 -> 6.5364715 | I14: =SUM($C26:$L26)/I12 -> 7.1490839 | J14: =SUM($C27:$L27)/J12 -> 7.8019036 | K14: =SUM($C28:$L28)/K12 -> 8.4972883
A15: Unlevered IRR | B15: =IFERROR(IRR($B32:$L32),IFERROR(IRR($B32:$L32,-0.5),"n/a")) -> 0.8111841 | C15: =IFERROR(IRR($B33:$L33),IFERROR(IRR($B33:$L33,-0.5),"n/a")) -> 0.42540383 | D15: =IFERROR(IRR($B34:$L34),IFERROR(IRR($B34:$L34,-0.5),"n/a")) -> 0.31679677 | E15: =IFERROR(IRR($B35:$L35),IFERROR(IRR($B35:$L35,-0.5),"n/a")) -> 0.26606433 | F15: =IFERROR(IRR($B36:$L36),IFERROR(IRR($B36:$L36,-0.5),"n/a")) -> 0.23658 | G15: =IFERROR(IRR($B37:$L37),IFERROR(IRR($B37:$L37,-0.5),"n/a")) -> 0.2173068 | H15: =IFERROR(IRR($B38:$L38),IFERROR(IRR($B38:$L38,-0.5),"n/a")) -> 0.20390984 | I15: =IFERROR(IRR($B39:$L39),IFERROR(IRR($B39:$L39,-0.5),"n/a")) -> 0.1941116 | J15: =IFERROR(IRR($B40:$L40),IFERROR(IRR($B40:$L40,-0.5),"n/a")) -> 0.18667406 | K15: =IFERROR(IRR($B41:$L41),IFERROR(IRR($B41:$L41,-0.5),"n/a")) -> 0.18086651
A17: Levered cash flow to equity by exit year
A18: Exit Year / Period | B18: 0 | C18: 1 | D18: 2 | E18: 3 | F18: 4 | G18: 5 | H18: 6 | I18: 7 | J18: 8 | K18: 9 | L18: 10 | N18: IRR | O18: EM | P18: Profit
A19: 1 | B19: =-'Cash Flow Model'!$E$8 -> -520575.08 | C19: =IF(C$18<$A19,INDEX('Cash Flow Model'!$C$24:$L$24,C$18),IF(C$18=$A19,INDEX($B$11:$K$11,$A19),0)) -> 1842875.9 | D19: =IF(D$18<$A19,INDEX('Cash Flow Model'!$C$24:$L$24,D$18),IF(D$18=$A19,INDEX($B$11:$K$11,$A19),0)) -> 0 | E19: =IF(E$18<$A19,INDEX('Cash Flow Model'!$C$24:$L$24,E$18),IF(E$18=$A19,INDEX($B$11:$K$11,$A19),0)) -> 0 | F19: =IF(F$18<$A19,INDEX('Cash Flow Model'!$C$24:$L$24,F$18),IF(F$18=$A19,INDEX($B$11:$K$11,$A19),0)) -> 0 | G19: =IF(G$18<$A19,INDEX('Cash Flow Model'!$C$24:$L$24,G$18),IF(G$18=$A19,INDEX($B$11:$K$11,$A19),0)) -> 0 | H19: =IF(H$18<$A19,INDEX('Cash Flow Model'!$C$24:$L$24,H$18),IF(H$18=$A19,INDEX($B$11:$K$11,$A19),0)) -> 0 | I19: =IF(I$18<$A19,INDEX('Cash Flow Model'!$C$24:$L$24,I$18),IF(I$18=$A19,INDEX($B$11:$K$11,$A19),0)) -> 0 | J19: =IF(J$18<$A19,INDEX('Cash Flow Model'!$C$24:$L$24,J$18),IF(J$18=$A19,INDEX($B$11:$K$11,$A19),0)) -> 0 | ... L19: =IF(L$18<$A19,INDEX('Cash Flow Model'!$C$24:$L$24,L$18),IF(L$18=$A19,INDEX($B$11:$K$11,$A19),0)) -> 0 | N19: =IFERROR(IRR(B19:L19),0) -> 2.540077 | O19: =SUM(C19:L19)/'Cash Flow Model'!$E$8 -> 3.540077 | P19: =SUM(C19:L19)-'Cash Flow Model'!$E$8 -> 1322300.8
A20: 2 | B20: =-'Cash Flow Model'!$E$8 -> -520575.08 | C20: =IF(C$18<$A20,INDEX('Cash Flow Model'!$C$24:$L$24,C$18),IF(C$18=$A20,INDEX($B$11:$K$11,$A20),0)) -> 83206.148 | D20: =IF(D$18<$A20,INDEX('Cash Flow Model'!$C$24:$L$24,D$18),IF(D$18=$A20,INDEX($B$11:$K$11,$A20),0)) -> 1980911.1 | E20: =IF(E$18<$A20,INDEX('Cash Flow Model'!$C$24:$L$24,E$18),IF(E$18=$A20,INDEX($B$11:$K$11,$A20),0)) -> 0 | F20: =IF(F$18<$A20,INDEX('Cash Flow Model'!$C$24:$L$24,F$18),IF(F$18=$A20,INDEX($B$11:$K$11,$A20),0)) -> 0 | G20: =IF(G$18<$A20,INDEX('Cash Flow Model'!$C$24:$L$24,G$18),IF(G$18=$A20,INDEX($B$11:$K$11,$A20),0)) -> 0 | H20: =IF(H$18<$A20,INDEX('Cash Flow Model'!$C$24:$L$24,H$18),IF(H$18=$A20,INDEX($B$11:$K$11,$A20),0)) -> 0 | I20: =IF(I$18<$A20,INDEX('Cash Flow Model'!$C$24:$L$24,I$18),IF(I$18=$A20,INDEX($B$11:$K$11,$A20),0)) -> 0 | J20: =IF(J$18<$A20,INDEX('Cash Flow Model'!$C$24:$L$24,J$18),IF(J$18=$A20,INDEX($B$11:$K$11,$A20),0)) -> 0 | ... L20: =IF(L$18<$A20,INDEX('Cash Flow Model'!$C$24:$L$24,L$18),IF(L$18=$A20,INDEX($B$11:$K$11,$A20),0)) -> 0 | N20: =IFERROR(IRR(B20:L20),0) -> 1.0322553 | O20: =SUM(C20:L20)/'Cash Flow Model'!$E$8 -> 3.9650711 | P20: =SUM(C20:L20)-'Cash Flow Model'!$E$8 -> 1543542.1
A21: 3 | B21: =-'Cash Flow Model'!$E$8 -> -520575.08 | C21: =IF(C$18<$A21,INDEX('Cash Flow Model'!$C$24:$L$24,C$18),IF(C$18=$A21,INDEX($B$11:$K$11,$A21),0)) -> 83206.148 | D21: =IF(D$18<$A21,INDEX('Cash Flow Model'!$C$24:$L$24,D$18),IF(D$18=$A21,INDEX($B$11:$K$11,$A21),0)) -> 90379.028 | E21: =IF(E$18<$A21,INDEX('Cash Flow Model'!$C$24:$L$24,E$18),IF(E$18=$A21,INDEX($B$11:$K$11,$A21),0)) -> 2127823.5 | F21: =IF(F$18<$A21,INDEX('Cash Flow Model'!$C$24:$L$24,F$18),IF(F$18=$A21,INDEX($B$11:$K$11,$A21),0)) -> 0 | G21: =IF(G$18<$A21,INDEX('Cash Flow Model'!$C$24:$L$24,G$18),IF(G$18=$A21,INDEX($B$11:$K$11,$A21),0)) -> 0 | H21: =IF(H$18<$A21,INDEX('Cash Flow Model'!$C$24:$L$24,H$18),IF(H$18=$A21,INDEX($B$11:$K$11,$A21),0)) -> 0 | I21: =IF(I$18<$A21,INDEX('Cash Flow Model'!$C$24:$L$24,I$18),IF(I$18=$A21,INDEX($B$11:$K$11,$A21),0)) -> 0 | J21: =IF(J$18<$A21,INDEX('Cash Flow Model'!$C$24:$L$24,J$18),IF(J$18=$A21,INDEX($B$11:$K$11,$A21),0)) -> 0 | ... L21: =IF(L$18<$A21,INDEX('Cash Flow Model'!$C$24:$L$24,L$18),IF(L$18=$A21,INDEX($B$11:$K$11,$A21),0)) -> 0 | N21: =IFERROR(IRR(B21:L21),0) -> 0.69134222 | O21: =SUM(C21:L21)/'Cash Flow Model'!$E$8 -> 4.4208968 | P21: =SUM(C21:L21)-'Cash Flow Model'!$E$8 -> 1780833.6
A22: 4 | B22: =-'Cash Flow Model'!$E$8 -> -520575.08 | C22: =IF(C$18<$A22,INDEX('Cash Flow Model'!$C$24:$L$24,C$18),IF(C$18=$A22,INDEX($B$11:$K$11,$A22),0)) -> 83206.148 | D22: =IF(D$18<$A22,INDEX('Cash Flow Model'!$C$24:$L$24,D$18),IF(D$18=$A22,INDEX($B$11:$K$11,$A22),0)) -> 90379.028 | E22: =IF(E$18<$A22,INDEX('Cash Flow Model'!$C$24:$L$24,E$18),IF(E$18=$A22,INDEX($B$11:$K$11,$A22),0)) -> 98008.527 | F22: =IF(F$18<$A22,INDEX('Cash Flow Model'!$C$24:$L$24,F$18),IF(F$18=$A22,INDEX($B$11:$K$11,$A22),0)) -> 2284146.1 | G22: =IF(G$18<$A22,INDEX('Cash Flow Model'!$C$24:$L$24,G$18),IF(G$18=$A22,INDEX($B$11:$K$11,$A22),0)) -> 0 | H22: =IF(H$18<$A22,INDEX('Cash Flow Model'!$C$24:$L$24,H$18),IF(H$18=$A22,INDEX($B$11:$K$11,$A22),0)) -> 0 | I22: =IF(I$18<$A22,INDEX('Cash Flow Model'!$C$24:$L$24,I$18),IF(I$18=$A22,INDEX($B$11:$K$11,$A22),0)) -> 0 | J22: =IF(J$18<$A22,INDEX('Cash Flow Model'!$C$24:$L$24,J$18),IF(J$18=$A22,INDEX($B$11:$K$11,$A22),0)) -> 0 | ... L22: =IF(L$18<$A22,INDEX('Cash Flow Model'!$C$24:$L$24,L$18),IF(L$18=$A22,INDEX($B$11:$K$11,$A22),0)) -> 0 | N22: =IFERROR(IRR(B22:L22),0) -> 0.54380381 | O22: =SUM(C22:L22)/'Cash Flow Model'!$E$8 -> 4.9094547 | P22: =SUM(C22:L22)-'Cash Flow Model'!$E$8 -> 2035164.7
A23: 5 | B23: =-'Cash Flow Model'!$E$8 -> -520575.08 | C23: =IF(C$18<$A23,INDEX('Cash Flow Model'!$C$24:$L$24,C$18),IF(C$18=$A23,INDEX($B$11:$K$11,$A23),0)) -> 83206.148 | D23: =IF(D$18<$A23,INDEX('Cash Flow Model'!$C$24:$L$24,D$18),IF(D$18=$A23,INDEX($B$11:$K$11,$A23),0)) -> 90379.028 | E23: =IF(E$18<$A23,INDEX('Cash Flow Model'!$C$24:$L$24,E$18),IF(E$18=$A23,INDEX($B$11:$K$11,$A23),0)) -> 98008.527 | F23: =IF(F$18<$A23,INDEX('Cash Flow Model'!$C$24:$L$24,F$18),IF(F$18=$A23,INDEX($B$11:$K$11,$A23),0)) -> 106121.48 | G23: =IF(G$18<$A23,INDEX('Cash Flow Model'!$C$24:$L$24,G$18),IF(G$18=$A23,INDEX($B$11:$K$11,$A23),0)) -> 2445395.8 | H23: =IF(H$18<$A23,INDEX('Cash Flow Model'!$C$24:$L$24,H$18),IF(H$18=$A23,INDEX($B$11:$K$11,$A23),0)) -> 0 | I23: =IF(I$18<$A23,INDEX('Cash Flow Model'!$C$24:$L$24,I$18),IF(I$18=$A23,INDEX($B$11:$K$11,$A23),0)) -> 0 | J23: =IF(J$18<$A23,INDEX('Cash Flow Model'!$C$24:$L$24,J$18),IF(J$18=$A23,INDEX($B$11:$K$11,$A23),0)) -> 0 | ... L23: =IF(L$18<$A23,INDEX('Cash Flow Model'!$C$24:$L$24,L$18),IF(L$18=$A23,INDEX($B$11:$K$11,$A23),0)) -> 0 | N23: =IFERROR(IRR(B23:L23),0) -> 0.46154208 | O23: =SUM(C23:L23)/'Cash Flow Model'!$E$8 -> 5.4230621 | P23: =SUM(C23:L23)-'Cash Flow Model'!$E$8 -> 2302535.9
A24: 6 | B24: =-'Cash Flow Model'!$E$8 -> -520575.08 | C24: =IF(C$18<$A24,INDEX('Cash Flow Model'!$C$24:$L$24,C$18),IF(C$18=$A24,INDEX($B$11:$K$11,$A24),0)) -> 83206.148 | D24: =IF(D$18<$A24,INDEX('Cash Flow Model'!$C$24:$L$24,D$18),IF(D$18=$A24,INDEX($B$11:$K$11,$A24),0)) -> 90379.028 | E24: =IF(E$18<$A24,INDEX('Cash Flow Model'!$C$24:$L$24,E$18),IF(E$18=$A24,INDEX($B$11:$K$11,$A24),0)) -> 98008.527 | F24: =IF(F$18<$A24,INDEX('Cash Flow Model'!$C$24:$L$24,F$18),IF(F$18=$A24,INDEX($B$11:$K$11,$A24),0)) -> 106121.48 | G24: =IF(G$18<$A24,INDEX('Cash Flow Model'!$C$24:$L$24,G$18),IF(G$18=$A24,INDEX($B$11:$K$11,$A24),0)) -> 114455.1 | H24: =IF(H$18<$A24,INDEX('Cash Flow Model'!$C$24:$L$24,H$18),IF(H$18=$A24,INDEX($B$11:$K$11,$A24),0)) -> 2611412.3 | I24: =IF(I$18<$A24,INDEX('Cash Flow Model'!$C$24:$L$24,I$18),IF(I$18=$A24,INDEX($B$11:$K$11,$A24),0)) -> 0 | J24: =IF(J$18<$A24,INDEX('Cash Flow Model'!$C$24:$L$24,J$18),IF(J$18=$A24,INDEX($B$11:$K$11,$A24),0)) -> 0 | ... L24: =IF(L$18<$A24,INDEX('Cash Flow Model'!$C$24:$L$24,L$18),IF(L$18=$A24,INDEX($B$11:$K$11,$A24),0)) -> 0 | N24: =IFERROR(IRR(B24:L24),0) -> 0.40918068 | O24: =SUM(C24:L24)/'Cash Flow Model'!$E$8 -> 5.9618348 | P24: =SUM(C24:L24)-'Cash Flow Model'!$E$8 -> 2583007.5
A25: 7 | B25: =-'Cash Flow Model'!$E$8 -> -520575.08 | C25: =IF(C$18<$A25,INDEX('Cash Flow Model'!$C$24:$L$24,C$18),IF(C$18=$A25,INDEX($B$11:$K$11,$A25),0)) -> 83206.148 | D25: =IF(D$18<$A25,INDEX('Cash Flow Model'!$C$24:$L$24,D$18),IF(D$18=$A25,INDEX($B$11:$K$11,$A25),0)) -> 90379.028 | E25: =IF(E$18<$A25,INDEX('Cash Flow Model'!$C$24:$L$24,E$18),IF(E$18=$A25,INDEX($B$11:$K$11,$A25),0)) -> 98008.527 | F25: =IF(F$18<$A25,INDEX('Cash Flow Model'!$C$24:$L$24,F$18),IF(F$18=$A25,INDEX($B$11:$K$11,$A25),0)) -> 106121.48 | G25: =IF(G$18<$A25,INDEX('Cash Flow Model'!$C$24:$L$24,G$18),IF(G$18=$A25,INDEX($B$11:$K$11,$A25),0)) -> 114455.1 | H25: =IF(H$18<$A25,INDEX('Cash Flow Model'!$C$24:$L$24,H$18),IF(H$18=$A25,INDEX($B$11:$K$11,$A25),0)) -> 122995.65 | I25: =IF(I$18<$A25,INDEX('Cash Flow Model'!$C$24:$L$24,I$18),IF(I$18=$A25,INDEX($B$11:$K$11,$A25),0)) -> 2787558.2 | J25: =IF(J$18<$A25,INDEX('Cash Flow Model'!$C$24:$L$24,J$18),IF(J$18=$A25,INDEX($B$11:$K$11,$A25),0)) -> 0 | ... L25: =IF(L$18<$A25,INDEX('Cash Flow Model'!$C$24:$L$24,L$18),IF(L$18=$A25,INDEX($B$11:$K$11,$A25),0)) -> 0 | N25: =IFERROR(IRR(B25:L25),0) -> 0.3732893 | O25: =SUM(C25:L25)/'Cash Flow Model'!$E$8 -> 6.5364715 | P25: =SUM(C25:L25)-'Cash Flow Model'!$E$8 -> 2882149.1
A26: 8 | B26: =-'Cash Flow Model'!$E$8 -> -520575.08 | C26: =IF(C$18<$A26,INDEX('Cash Flow Model'!$C$24:$L$24,C$18),IF(C$18=$A26,INDEX($B$11:$K$11,$A26),0)) -> 83206.148 | D26: =IF(D$18<$A26,INDEX('Cash Flow Model'!$C$24:$L$24,D$18),IF(D$18=$A26,INDEX($B$11:$K$11,$A26),0)) -> 90379.028 | E26: =IF(E$18<$A26,INDEX('Cash Flow Model'!$C$24:$L$24,E$18),IF(E$18=$A26,INDEX($B$11:$K$11,$A26),0)) -> 98008.527 | F26: =IF(F$18<$A26,INDEX('Cash Flow Model'!$C$24:$L$24,F$18),IF(F$18=$A26,INDEX($B$11:$K$11,$A26),0)) -> 106121.48 | G26: =IF(G$18<$A26,INDEX('Cash Flow Model'!$C$24:$L$24,G$18),IF(G$18=$A26,INDEX($B$11:$K$11,$A26),0)) -> 114455.1 | H26: =IF(H$18<$A26,INDEX('Cash Flow Model'!$C$24:$L$24,H$18),IF(H$18=$A26,INDEX($B$11:$K$11,$A26),0)) -> 122995.65 | I26: =IF(I$18<$A26,INDEX('Cash Flow Model'!$C$24:$L$24,I$18),IF(I$18=$A26,INDEX($B$11:$K$11,$A26),0)) -> 132047.74 | J26: =IF(J$18<$A26,INDEX('Cash Flow Model'!$C$24:$L$24,J$18),IF(J$18=$A26,INDEX($B$11:$K$11,$A26),0)) -> 2974421.2 | ... L26: =IF(L$18<$A26,INDEX('Cash Flow Model'!$C$24:$L$24,L$18),IF(L$18=$A26,INDEX($B$11:$K$11,$A26),0)) -> 0 | N26: =IFERROR(IRR(B26:L26),0) -> 0.34727558 | O26: =SUM(C26:L26)/'Cash Flow Model'!$E$8 -> 7.1490839 | P26: =SUM(C26:L26)-'Cash Flow Model'!$E$8 -> 3201059.8
A27: 9 | B27: =-'Cash Flow Model'!$E$8 -> -520575.08 | C27: =IF(C$18<$A27,INDEX('Cash Flow Model'!$C$24:$L$24,C$18),IF(C$18=$A27,INDEX($B$11:$K$11,$A27),0)) -> 83206.148 | D27: =IF(D$18<$A27,INDEX('Cash Flow Model'!$C$24:$L$24,D$18),IF(D$18=$A27,INDEX($B$11:$K$11,$A27),0)) -> 90379.028 | E27: =IF(E$18<$A27,INDEX('Cash Flow Model'!$C$24:$L$24,E$18),IF(E$18=$A27,INDEX($B$11:$K$11,$A27),0)) -> 98008.527 | F27: =IF(F$18<$A27,INDEX('Cash Flow Model'!$C$24:$L$24,F$18),IF(F$18=$A27,INDEX($B$11:$K$11,$A27),0)) -> 106121.48 | G27: =IF(G$18<$A27,INDEX('Cash Flow Model'!$C$24:$L$24,G$18),IF(G$18=$A27,INDEX($B$11:$K$11,$A27),0)) -> 114455.1 | H27: =IF(H$18<$A27,INDEX('Cash Flow Model'!$C$24:$L$24,H$18),IF(H$18=$A27,INDEX($B$11:$K$11,$A27),0)) -> 122995.65 | I27: =IF(I$18<$A27,INDEX('Cash Flow Model'!$C$24:$L$24,I$18),IF(I$18=$A27,INDEX($B$11:$K$11,$A27),0)) -> 132047.74 | J27: =IF(J$18<$A27,INDEX('Cash Flow Model'!$C$24:$L$24,J$18),IF(J$18=$A27,INDEX($B$11:$K$11,$A27),0)) -> 141640.16 | ... L27: =IF(L$18<$A27,INDEX('Cash Flow Model'!$C$24:$L$24,L$18),IF(L$18=$A27,INDEX($B$11:$K$11,$A27),0)) -> 0 | N27: =IFERROR(IRR(B27:L27),0) -> 0.3276499 | O27: =SUM(C27:L27)/'Cash Flow Model'!$E$8 -> 7.8019036 | P27: =SUM(C27:L27)-'Cash Flow Model'!$E$8 -> 3540901.5
A28: 10 | B28: =-'Cash Flow Model'!$E$8 -> -520575.08 | C28: =IF(C$18<$A28,INDEX('Cash Flow Model'!$C$24:$L$24,C$18),IF(C$18=$A28,INDEX($B$11:$K$11,$A28),0)) -> 83206.148 | D28: =IF(D$18<$A28,INDEX('Cash Flow Model'!$C$24:$L$24,D$18),IF(D$18=$A28,INDEX($B$11:$K$11,$A28),0)) -> 90379.028 | E28: =IF(E$18<$A28,INDEX('Cash Flow Model'!$C$24:$L$24,E$18),IF(E$18=$A28,INDEX($B$11:$K$11,$A28),0)) -> 98008.527 | F28: =IF(F$18<$A28,INDEX('Cash Flow Model'!$C$24:$L$24,F$18),IF(F$18=$A28,INDEX($B$11:$K$11,$A28),0)) -> 106121.48 | G28: =IF(G$18<$A28,INDEX('Cash Flow Model'!$C$24:$L$24,G$18),IF(G$18=$A28,INDEX($B$11:$K$11,$A28),0)) -> 114455.1 | H28: =IF(H$18<$A28,INDEX('Cash Flow Model'!$C$24:$L$24,H$18),IF(H$18=$A28,INDEX($B$11:$K$11,$A28),0)) -> 122995.65 | I28: =IF(I$18<$A28,INDEX('Cash Flow Model'!$C$24:$L$24,I$18),IF(I$18=$A28,INDEX($B$11:$K$11,$A28),0)) -> 132047.74 | J28: =IF(J$18<$A28,INDEX('Cash Flow Model'!$C$24:$L$24,J$18),IF(J$18=$A28,INDEX($B$11:$K$11,$A28),0)) -> 141640.16 | ... L28: =IF(L$18<$A28,INDEX('Cash Flow Model'!$C$24:$L$24,L$18),IF(L$18=$A28,INDEX($B$11:$K$11,$A28),0)) -> 3382819.4 | N28: =IFERROR(IRR(B28:L28),0) -> 0.31239317 | O28: =SUM(C28:L28)/'Cash Flow Model'!$E$8 -> 8.4972883 | P28: =SUM(C28:L28)-'Cash Flow Model'!$E$8 -> 3902901.5
A30: Unlevered cash flow by exit year
A31: Exit Year / Period | B31: 0 | C31: 1 | D31: 2 | E31: 3 | F31: 4 | G31: 5 | H31: 6 | I31: 7 | J31: 8 | K31: 9 | L31: 10
A32: 1 | B32: =-'Cash Flow Model'!$E$6 -> -1735250.3 | C32: =IF(C$31<$A32,INDEX('Cash Flow Model'!$C$19:$L$19,C$31),IF(C$31=$A32,INDEX('Cash Flow Model'!$C$19:$L$19,C$31)+INDEX($B$6:$K$6,$A32)-INDEX($B$7:$K$7,$A32),0)) -> 3142857.7 | D32: =IF(D$31<$A32,INDEX('Cash Flow Model'!$C$19:$L$19,D$31),IF(D$31=$A32,INDEX('Cash Flow Model'!$C$19:$L$19,D$31)+INDEX($B$6:$K$6,$A32)-INDEX($B$7:$K$7,$A32),0)) -> 0 | E32: =IF(E$31<$A32,INDEX('Cash Flow Model'!$C$19:$L$19,E$31),IF(E$31=$A32,INDEX('Cash Flow Model'!$C$19:$L$19,E$31)+INDEX($B$6:$K$6,$A32)-INDEX($B$7:$K$7,$A32),0)) -> 0 | F32: =IF(F$31<$A32,INDEX('Cash Flow Model'!$C$19:$L$19,F$31),IF(F$31=$A32,INDEX('Cash Flow Model'!$C$19:$L$19,F$31)+INDEX($B$6:$K$6,$A32)-INDEX($B$7:$K$7,$A32),0)) -> 0 | G32: =IF(G$31<$A32,INDEX('Cash Flow Model'!$C$19:$L$19,G$31),IF(G$31=$A32,INDEX('Cash Flow Model'!$C$19:$L$19,G$31)+INDEX($B$6:$K$6,$A32)-INDEX($B$7:$K$7,$A32),0)) -> 0 | H32: =IF(H$31<$A32,INDEX('Cash Flow Model'!$C$19:$L$19,H$31),IF(H$31=$A32,INDEX('Cash Flow Model'!$C$19:$L$19,H$31)+INDEX($B$6:$K$6,$A32)-INDEX($B$7:$K$7,$A32),0)) -> 0 | I32: =IF(I$31<$A32,INDEX('Cash Flow Model'!$C$19:$L$19,I$31),IF(I$31=$A32,INDEX('Cash Flow Model'!$C$19:$L$19,I$31)+INDEX($B$6:$K$6,$A32)-INDEX($B$7:$K$7,$A32),0)) -> 0 | J32: =IF(J$31<$A32,INDEX('Cash Flow Model'!$C$19:$L$19,J$31),IF(J$31=$A32,INDEX('Cash Flow Model'!$C$19:$L$19,J$31)+INDEX($B$6:$K$6,$A32)-INDEX($B$7:$K$7,$A32),0)) -> 0 | ... L32: =IF(L$31<$A32,INDEX('Cash Flow Model'!$C$19:$L$19,L$31),IF(L$31=$A32,INDEX('Cash Flow Model'!$C$19:$L$19,L$31)+INDEX($B$6:$K$6,$A32)-INDEX($B$7:$K$7,$A32),0)) -> 0
A33: 2 | B33: =-'Cash Flow Model'!$E$6 -> -1735250.3 | C33: =IF(C$31<$A33,INDEX('Cash Flow Model'!$C$19:$L$19,C$31),IF(C$31=$A33,INDEX('Cash Flow Model'!$C$19:$L$19,C$31)+INDEX($B$6:$K$6,$A33)-INDEX($B$7:$K$7,$A33),0)) -> 181318.71 | D33: =IF(D$31<$A33,INDEX('Cash Flow Model'!$C$19:$L$19,D$31),IF(D$31=$A33,INDEX('Cash Flow Model'!$C$19:$L$19,D$31)+INDEX($B$6:$K$6,$A33)-INDEX($B$7:$K$7,$A33),0)) -> 3267187.6 | E33: =IF(E$31<$A33,INDEX('Cash Flow Model'!$C$19:$L$19,E$31),IF(E$31=$A33,INDEX('Cash Flow Model'!$C$19:$L$19,E$31)+INDEX($B$6:$K$6,$A33)-INDEX($B$7:$K$7,$A33),0)) -> 0 | F33: =IF(F$31<$A33,INDEX('Cash Flow Model'!$C$19:$L$19,F$31),IF(F$31=$A33,INDEX('Cash Flow Model'!$C$19:$L$19,F$31)+INDEX($B$6:$K$6,$A33)-INDEX($B$7:$K$7,$A33),0)) -> 0 | G33: =IF(G$31<$A33,INDEX('Cash Flow Model'!$C$19:$L$19,G$31),IF(G$31=$A33,INDEX('Cash Flow Model'!$C$19:$L$19,G$31)+INDEX($B$6:$K$6,$A33)-INDEX($B$7:$K$7,$A33),0)) -> 0 | H33: =IF(H$31<$A33,INDEX('Cash Flow Model'!$C$19:$L$19,H$31),IF(H$31=$A33,INDEX('Cash Flow Model'!$C$19:$L$19,H$31)+INDEX($B$6:$K$6,$A33)-INDEX($B$7:$K$7,$A33),0)) -> 0 | I33: =IF(I$31<$A33,INDEX('Cash Flow Model'!$C$19:$L$19,I$31),IF(I$31=$A33,INDEX('Cash Flow Model'!$C$19:$L$19,I$31)+INDEX($B$6:$K$6,$A33)-INDEX($B$7:$K$7,$A33),0)) -> 0 | J33: =IF(J$31<$A33,INDEX('Cash Flow Model'!$C$19:$L$19,J$31),IF(J$31=$A33,INDEX('Cash Flow Model'!$C$19:$L$19,J$31)+INDEX($B$6:$K$6,$A33)-INDEX($B$7:$K$7,$A33),0)) -> 0 | ... L33: =IF(L$31<$A33,INDEX('Cash Flow Model'!$C$19:$L$19,L$31),IF(L$31=$A33,INDEX('Cash Flow Model'!$C$19:$L$19,L$31)+INDEX($B$6:$K$6,$A33)-INDEX($B$7:$K$7,$A33),0)) -> 0
A34: 3 | B34: =-'Cash Flow Model'!$E$6 -> -1735250.3 | C34: =IF(C$31<$A34,INDEX('Cash Flow Model'!$C$19:$L$19,C$31),IF(C$31=$A34,INDEX('Cash Flow Model'!$C$19:$L$19,C$31)+INDEX($B$6:$K$6,$A34)-INDEX($B$7:$K$7,$A34),0)) -> 181318.71 | D34: =IF(D$31<$A34,INDEX('Cash Flow Model'!$C$19:$L$19,D$31),IF(D$31=$A34,INDEX('Cash Flow Model'!$C$19:$L$19,D$31)+INDEX($B$6:$K$6,$A34)-INDEX($B$7:$K$7,$A34),0)) -> 188491.59 | E34: =IF(E$31<$A34,INDEX('Cash Flow Model'!$C$19:$L$19,E$31),IF(E$31=$A34,INDEX('Cash Flow Model'!$C$19:$L$19,E$31)+INDEX($B$6:$K$6,$A34)-INDEX($B$7:$K$7,$A34),0)) -> 3399432.3 | F34: =IF(F$31<$A34,INDEX('Cash Flow Model'!$C$19:$L$19,F$31),IF(F$31=$A34,INDEX('Cash Flow Model'!$C$19:$L$19,F$31)+INDEX($B$6:$K$6,$A34)-INDEX($B$7:$K$7,$A34),0)) -> 0 | G34: =IF(G$31<$A34,INDEX('Cash Flow Model'!$C$19:$L$19,G$31),IF(G$31=$A34,INDEX('Cash Flow Model'!$C$19:$L$19,G$31)+INDEX($B$6:$K$6,$A34)-INDEX($B$7:$K$7,$A34),0)) -> 0 | H34: =IF(H$31<$A34,INDEX('Cash Flow Model'!$C$19:$L$19,H$31),IF(H$31=$A34,INDEX('Cash Flow Model'!$C$19:$L$19,H$31)+INDEX($B$6:$K$6,$A34)-INDEX($B$7:$K$7,$A34),0)) -> 0 | I34: =IF(I$31<$A34,INDEX('Cash Flow Model'!$C$19:$L$19,I$31),IF(I$31=$A34,INDEX('Cash Flow Model'!$C$19:$L$19,I$31)+INDEX($B$6:$K$6,$A34)-INDEX($B$7:$K$7,$A34),0)) -> 0 | J34: =IF(J$31<$A34,INDEX('Cash Flow Model'!$C$19:$L$19,J$31),IF(J$31=$A34,INDEX('Cash Flow Model'!$C$19:$L$19,J$31)+INDEX($B$6:$K$6,$A34)-INDEX($B$7:$K$7,$A34),0)) -> 0 | ... L34: =IF(L$31<$A34,INDEX('Cash Flow Model'!$C$19:$L$19,L$31),IF(L$31=$A34,INDEX('Cash Flow Model'!$C$19:$L$19,L$31)+INDEX($B$6:$K$6,$A34)-INDEX($B$7:$K$7,$A34),0)) -> 0
