Workbook

Sheet Investment Summary
A1: INVESTMENT SUMMARY
A2: One-page dashboard — all figures link live to the model. Placeholder assumptions; replace on the Assumptions tab.
A4: KEY METRICS
A5: Purchase Price | B5: =Assumptions!$B$8 -> 1300000
A6: Price per Pad | B6: =Valuation!B17 -> 16250
A7: Total Pads | B7: =Assumptions!$B$16 -> 80
A8: Occupancy at Close | B8: =Assumptions!$B$17/Assumptions!$B$16 -> 0.75
A9: Stabilized Occupancy | B9: =Assumptions!$B$9 -> 0.92
A10: Going-in Cap Rate | B10: =Valuation!B15 -> 0.065557626
A11: Year-1 NOI | B11: =Valuation!B14 -> 85224.913
A12: Stabilized NOI (Yr 3) | B12: =Valuation!B16 -> 132685.85
A13: Initial Loan | B13: =Acquisition!$B$10 -> 910000
A14: Initial LTV | B14: =Acquisition!B26 -> 0.7
A15: Equity Required | B15: =Acquisition!$B$23 -> 600100
A16: Refi Net Proceeds (Yr 3) | B16: =Refinance!$B$14 -> 616028.14
A17: Exit Value | B17: =Exit!B9 -> 2284928.2
A18: Net Sale Proceeds | B18: =Exit!$B$13 -> 701987.73
A20: RETURNS
A21: Levered IRR | B21: ='Equity Returns'!B16 -> 0.27741656
A22: Equity Multiple | B22: ='Equity Returns'!B17 -> 2.5130314
A23: Avg Cash-on-Cash | B23: ='Equity Returns'!B19 -> 0.069377621
A24: Total Profit | B24: ='Equity Returns'!B18 -> 907970.15
A25: Hold Period (yrs) | B25: =Exit!B6 -> 5
A26: LP IRR / GP IRR | B26: ='LP GP Waterfall'!B23 -> 0.25405811
A27: LP Equity Multiple | B27: ='LP GP Waterfall'!B24 -> 2.3182501
A40: Chart data (annual) | C40: Y1 | D40: Y2 | E40: Y3 | F40: Y4 | G40: Y5 | H40: Y6 | I40: Y7 | J40: Y8 | K40: Y9 | L40: Y10
A41: EGR | C41: =Valuation!C5 -> 330763.07 | D41: =Valuation!D5 -> 377116.46 | E41: =Valuation!E5 -> 392925.24 | F41: =Valuation!F5 -> 404620.2 | G41: =Valuation!G5 -> 416663.7 | H41: =Valuation!H5 -> 429066.12 | I41: =Valuation!I5 -> 441838.18 | J41: =Valuation!J5 -> 454990.9 | ... L41: =Valuation!L5 -> 482484.1
A42: NOI | C42: =Valuation!C7 -> 85224.913 | D42: =Valuation!D7 -> 123535.64 | E42: =Valuation!E7 -> 132685.85 | F42: =Valuation!F7 -> 137781.24 | G42: =Valuation!G7 -> 143057.36 | H42: =Valuation!H7 -> 148520.33 | I42: =Valuation!I7 -> 154176.48 | J42: =Valuation!J7 -> 160032.32 | ... L42: =Valuation!L7 -> 172370.28
A43: Occupancy | C43: =Revenue!C14 -> 0.86333333 | D43: =Revenue!D14 -> 0.92 | E43: =Revenue!E14 -> 0.92 | F43: =Revenue!F14 -> 0.92 | G43: =Revenue!G14 -> 0.92 | H43: =Revenue!H14 -> 0.92 | I43: =Revenue!I14 -> 0.92 | J43: =Revenue!J14 -> 0.92 | ... L43: =Revenue!L14 -> 0.92
A44: Debt Balance | C44: =INDEX('Debt Schedule'!D19:DS19,1,1*12) -> 910000 | D44: =INDEX('Debt Schedule'!D19:DS19,1,2*12) -> 910000 | E44: =INDEX('Debt Schedule'!D19:DS19,1,3*12) -> 1530525.2 | F44: =INDEX('Debt Schedule'!D19:DS19,1,4*12) -> 1511617.4 | G44: =INDEX('Debt Schedule'!D19:DS19,1,5*12) -> 1491543.3 | H44: =INDEX('Debt Schedule'!D19:DS19,1,6*12) -> 1470231.2 | I44: =INDEX('Debt Schedule'!D19:DS19,1,7*12) -> 1447604.6 | J44: =INDEX('Debt Schedule'!D19:DS19,1,8*12) -> 1423582.4 | K44: =INDEX('Debt Schedule'!D19:DS19,1,9*12) -> 1398078.6 | L44: =INDEX('Debt Schedule'!D19:DS19,1,10*12) -> 1371001.7
A46: IRR by exit year | C46: =Exit!I18 -> 0.56074197 | D46: =Exit!I19 -> 0.37852234 | E46: =Exit!I20 -> 0.29094732 | F46: =Exit!I21 -> 0.28458014 | G46: =Exit!I22 -> 0.27741656 | H46: =Exit!I23 -> 0.27033933 | I46: =Exit!I24 -> 0.26369184 | J46: =Exit!I25 -> 0.25758924 | K46: =Exit!I26 -> 0.2520483 | L46: =Exit!I27 -> 0.24243309

Sheet Rent Roll
A1: RENT ROLL
A2: Unit-level detail — seeded to tie to Assumptions; edit per-unit and reconcile on Checks
A4: Lot ID | B4: Unit Type | C4: Status | D4: Current Rent ($/mo) | E4: Market Rent ($/mo) | F4: Rent Growth | G4: Lease Expiration | H4: Potential Rent | I4: Actual Rent | J4: Vacancy Loss | K4: Other Income | L4: Notes
A5: P-001 | B5: POH | C5: Occupied | D5: =IF(C5="Occupied",Assumptions!$B$23,0) -> 350 | E5: =Assumptions!$B$24 -> 425 | F5: =Assumptions!$B$10 -> 0.03 | G5: MTM | H5: =E5 -> 425 | I5: =IF(C5="Occupied",D5,0) -> 350 | J5: =IF(C5="Vacant",E5,0) -> 0 | K5: =IF(C5="Occupied",Assumptions!$B$26,0) -> 20 | L5: POH — home rent extra
A6: P-002 | B6: POH | C6: Occupied | D6: =IF(C6="Occupied",Assumptions!$B$23,0) -> 350 | E6: =Assumptions!$B$24 -> 425 | F6: =Assumptions!$B$10 -> 0.03 | G6: MTM | H6: =E6 -> 425 | I6: =IF(C6="Occupied",D6,0) -> 350 | J6: =IF(C6="Vacant",E6,0) -> 0 | K6: =IF(C6="Occupied",Assumptions!$B$26,0) -> 20 | L6: POH — home rent extra
A7: P-003 | B7: POH | C7: Occupied | D7: =IF(C7="Occupied",Assumptions!$B$23,0) -> 350 | E7: =Assumptions!$B$24 -> 425 | F7: =Assumptions!$B$10 -> 0.03 | G7: MTM | H7: =E7 -> 425 | I7: =IF(C7="Occupied",D7,0) -> 350 | J7: =IF(C7="Vacant",E7,0) -> 0 | K7: =IF(C7="Occupied",Assumptions!$B$26,0) -> 20 | L7: POH — home rent extra
A8: P-004 | B8: POH | C8: Occupied | D8: =IF(C8="Occupied",Assumptions!$B$23,0) -> 350 | E8: =Assumptions!$B$24 -> 425 | F8: =Assumptions!$B$10 -> 0.03 | G8: MTM | H8: =E8 -> 425 | I8: =IF(C8="Occupied",D8,0) -> 350 | J8: =IF(C8="Vacant",E8,0) -> 0 | K8: =IF(C8="Occupied",Assumptions!$B$26,0) -> 20 | L8: POH — home rent extra
A9: P-005 | B9: POH | C9: Occupied | D9: =IF(C9="Occupied",Assumptions!$B$23,0) -> 350 | E9: =Assumptions!$B$24 -> 425 | F9: =Assumptions!$B$10 -> 0.03 | G9: MTM | H9: =E9 -> 425 | I9: =IF(C9="Occupied",D9,0) -> 350 | J9: =IF(C9="Vacant",E9,0) -> 0 | K9: =IF(C9="Occupied",Assumptions!$B$26,0) -> 20 | L9: POH — home rent extra
A10: P-006 | B10: POH | C10: Occupied | D10: =IF(C10="Occupied",Assumptions!$B$23,0) -> 350 | E10: =Assumptions!$B$24 -> 425 | F10: =Assumptions!$B$10 -> 0.03 | G10: MTM | H10: =E10 -> 425 | I10: =IF(C10="Occupied",D10,0) -> 350 | J10: =IF(C10="Vacant",E10,0) -> 0 | K10: =IF(C10="Occupied",Assumptions!$B$26,0) -> 20 | L10: POH — home rent extra
A11: P-007 | B11: POH | C11: Occupied | D11: =IF(C11="Occupied",Assumptions!$B$23,0) -> 350 | E11: =Assumptions!$B$24 -> 425 | F11: =Assumptions!$B$10 -> 0.03 | G11: MTM | H11: =E11 -> 425 | I11: =IF(C11="Occupied",D11,0) -> 350 | J11: =IF(C11="Vacant",E11,0) -> 0 | K11: =IF(C11="Occupied",Assumptions!$B$26,0) -> 20 | L11: POH — home rent extra
A12: P-008 | B12: POH | C12: Occupied | D12: =IF(C12="Occupied",Assumptions!$B$23,0) -> 350 | E12: =Assumptions!$B$24 -> 425 | F12: =Assumptions!$B$10 -> 0.03 | G12: MTM | H12: =E12 -> 425 | I12: =IF(C12="Occupied",D12,0) -> 350 | J12: =IF(C12="Vacant",E12,0) -> 0 | K12: =IF(C12="Occupied",Assumptions!$B$26,0) -> 20 | L12: POH — home rent extra
A13: P-009 | B13: POH | C13: Occupied | D13: =IF(C13="Occupied",Assumptions!$B$23,0) -> 350 | E13: =Assumptions!$B$24 -> 425 | F13: =Assumptions!$B$10 -> 0.03 | G13: MTM | H13: =E13 -> 425 | I13: =IF(C13="Occupied",D13,0) -> 350 | J13: =IF(C13="Vacant",E13,0) -> 0 | K13: =IF(C13="Occupied",Assumptions!$B$26,0) -> 20 | L13: POH — home rent extra
A14: P-010 | B14: POH | C14: Occupied | D14: =IF(C14="Occupied",Assumptions!$B$23,0) -> 350 | E14: =Assumptions!$B$24 -> 425 | F14: =Assumptions!$B$10 -> 0.03 | G14: MTM | H14: =E14 -> 425 | I14: =IF(C14="Occupied",D14,0) -> 350 | J14: =IF(C14="Vacant",E14,0) -> 0 | K14: =IF(C14="Occupied",Assumptions!$B$26,0) -> 20 | L14: POH — home rent extra
A15: P-011 | B15: TOH | C15: Occupied | D15: =IF(C15="Occupied",Assumptions!$B$23,0) -> 350 | E15: =Assumptions!$B$24 -> 425 | F15: =Assumptions!$B$10 -> 0.03 | G15: MTM | H15: =E15 -> 425 | I15: =IF(C15="Occupied",D15,0) -> 350 | J15: =IF(C15="Vacant",E15,0) -> 0 | K15: =IF(C15="Occupied",Assumptions!$B$26,0) -> 20
A16: P-012 | B16: TOH | C16: Occupied | D16: =IF(C16="Occupied",Assumptions!$B$23,0) -> 350 | E16: =Assumptions!$B$24 -> 425 | F16: =Assumptions!$B$10 -> 0.03 | G16: MTM | H16: =E16 -> 425 | I16: =IF(C16="Occupied",D16,0) -> 350 | J16: =IF(C16="Vacant",E16,0) -> 0 | K16: =IF(C16="Occupied",Assumptions!$B$26,0) -> 20
A17: P-013 | B17: TOH | C17: Occupied | D17: =IF(C17="Occupied",Assumptions!$B$23,0) -> 350 | E17: =Assumptions!$B$24 -> 425 | F17: =Assumptions!$B$10 -> 0.03 | G17: MTM | H17: =E17 -> 425 | I17: =IF(C17="Occupied",D17,0) -> 350 | J17: =IF(C17="Vacant",E17,0) -> 0 | K17: =IF(C17="Occupied",Assumptions!$B$26,0) -> 20
A18: P-014 | B18: TOH | C18: Occupied | D18: =IF(C18="Occupied",Assumptions!$B$23,0) -> 350 | E18: =Assumptions!$B$24 -> 425 | F18: =Assumptions!$B$10 -> 0.03 | G18: MTM | H18: =E18 -> 425 | I18: =IF(C18="Occupied",D18,0) -> 350 | J18: =IF(C18="Vacant",E18,0) -> 0 | K18: =IF(C18="Occupied",Assumptions!$B$26,0) -> 20
A19: P-015 | B19: TOH | C19: Occupied | D19: =IF(C19="Occupied",Assumptions!$B$23,0) -> 350 | E19: =Assumptions!$B$24 -> 425 | F19: =Assumptions!$B$10 -> 0.03 | G19: MTM | H19: =E19 -> 425 | I19: =IF(C19="Occupied",D19,0) -> 350 | J19: =IF(C19="Vacant",E19,0) -> 0 | K19: =IF(C19="Occupied",Assumptions!$B$26,0) -> 20
A20: P-016 | B20: TOH | C20: Occupied | D20: =IF(C20="Occupied",Assumptions!$B$23,0) -> 350 | E20: =Assumptions!$B$24 -> 425 | F20: =Assumptions!$B$10 -> 0.03 | G20: MTM | H20: =E20 -> 425 | I20: =IF(C20="Occupied",D20,0) -> 350 | J20: =IF(C20="Vacant",E20,0) -> 0 | K20: =IF(C20="Occupied",Assumptions!$B$26,0) -> 20
A21: P-017 | B21: TOH | C21: Occupied | D21: =IF(C21="Occupied",Assumptions!$B$23,0) -> 350 | E21: =Assumptions!$B$24 -> 425 | F21: =Assumptions!$B$10 -> 0.03 | G21: MTM | H21: =E21 -> 425 | I21: =IF(C21="Occupied",D21,0) -> 350 | J21: =IF(C21="Vacant",E21,0) -> 0 | K21: =IF(C21="Occupied",Assumptions!$B$26,0) -> 20
A22: P-018 | B22: TOH | C22: Occupied | D22: =IF(C22="Occupied",Assumptions!$B$23,0) -> 350 | E22: =Assumptions!$B$24 -> 425 | F22: =Assumptions!$B$10 -> 0.03 | G22: MTM | H22: =E22 -> 425 | I22: =IF(C22="Occupied",D22,0) -> 350 | J22: =IF(C22="Vacant",E22,0) -> 0 | K22: =IF(C22="Occupied",Assumptions!$B$26,0) -> 20
A23: P-019 | B23: TOH | C23: Occupied | D23: =IF(C23="Occupied",Assumptions!$B$23,0) -> 350 | E23: =Assumptions!$B$24 -> 425 | F23: =Assumptions!$B$10 -> 0.03 | G23: MTM | H23: =E23 -> 425 | I23: =IF(C23="Occupied",D23,0) -> 350 | J23: =IF(C23="Vacant",E23,0) -> 0 | K23: =IF(C23="Occupied",Assumptions!$B$26,0) -> 20
A24: P-020 | B24: TOH | C24: Occupied | D24: =IF(C24="Occupied",Assumptions!$B$23,0) -> 350 | E24: =Assumptions!$B$24 -> 425 | F24: =Assumptions!$B$10 -> 0.03 | G24: MTM | H24: =E24 -> 425 | I24: =IF(C24="Occupied",D24,0) -> 350 | J24: =IF(C24="Vacant",E24,0) -> 0 | K24: =IF(C24="Occupied",Assumptions!$B$26,0) -> 20
A25: P-021 | B25: TOH | C25: Occupied | D25: =IF(C25="Occupied",Assumptions!$B$23,0) -> 350 | E25: =Assumptions!$B$24 -> 425 | F25: =Assumptions!$B$10 -> 0.03 | G25: MTM | H25: =E25 -> 425 | I25: =IF(C25="Occupied",D25,0) -> 350 | J25: =IF(C25="Vacant",E25,0) -> 0 | K25: =IF(C25="Occupied",Assumptions!$B$26,0) -> 20
A26: P-022 | B26: TOH | C26: Occupied | D26: =IF(C26="Occupied",Assumptions!$B$23,0) -> 350 | E26: =Assumptions!$B$24 -> 425 | F26: =Assumptions!$B$10 -> 0.03 | G26: MTM | H26: =E26 -> 425 | I26: =IF(C26="Occupied",D26,0) -> 350 | J26: =IF(C26="Vacant",E26,0) -> 0 | K26: =IF(C26="Occupied",Assumptions!$B$26,0) -> 20
... A84: P-080 | B84: TOH | C84: Vacant | D84: =IF(C84="Occupied",Assumptions!$B$23,0) -> 0 | E84: =Assumptions!$B$24 -> 425 | F84: =Assumptions!$B$10 -> 0.03 | G84: MTM | H84: =E84 -> 425 | I84: =IF(C84="Occupied",D84,0) -> 0 | J84: =IF(C84="Vacant",E84,0) -> 425 | K84: =IF(C84="Occupied",Assumptions!$B$26,0) -> 0
A85: TOTALS / SUMMARY | H85: =SUM(H5:H84) -> 34000 | I85: =SUM(I5:I84) -> 21000 | J85: =SUM(J5:J84) -> 8500 | K85: =SUM(K5:K84) -> 1200
A87: Total pads (count) | B87: =COUNTA(A5:A84) -> 80
A88: Occupied pads (count) | B88: =COUNTIF(C5:C84,"Occupied") -> 60
A89: Avg in-place lot rent | B89: =IFERROR(AVERAGEIF(C5:C84,"Occupied",D5:D84),0) -> 350
A90: Monthly potential (market) rent | B90: =H85 -> 34000

Sheet Revenue
A1: REVENUE — ANNUAL
A2: Rolled up from the 120-month engine (green = linked to Monthly Operations)
C4: Year 1 | D4: Year 2 | E4: Year 3 | F4: Year 4 | G4: Year 5 | H4: Year 6 | I4: Year 7 | J4: Year 8 | K4: Year 9 | L4: Year 10
A5: Potential Gross Rent | C5: =SUM('Monthly Operations'!D11:O11) -> 336000 | D5: =SUM('Monthly Operations'!P11:AA11) -> 346080 | E5: =SUM('Monthly Operations'!AB11:AM11) -> 356462.4 | F5: =SUM('Monthly Operations'!AN11:AY11) -> 367156.27 | G5: =SUM('Monthly Operations'!AZ11:BK11) -> 378170.96 | H5: =SUM('Monthly Operations'!BL11:BW11) -> 389516.09 | I5: =SUM('Monthly Operations'!BX11:CI11) -> 401201.57 | J5: =SUM('Monthly Operations'!CJ11:CU11) -> 413237.62 | K5: =SUM('Monthly Operations'!CV11:DG11) -> 425634.75 | L5: =SUM('Monthly Operations'!DH11:DS11) -> 438403.79
A6: Less: Vacancy Loss | C6: =SUM('Monthly Operations'!D12:O12) -> -63373.333 | D6: =SUM('Monthly Operations'!P12:AA12) -> -31772.067 | E6: =SUM('Monthly Operations'!AB12:AM12) -> -28516.992 | F6: =SUM('Monthly Operations'!AN12:AY12) -> -29372.502 | G6: =SUM('Monthly Operations'!AZ12:BK12) -> -30253.677 | H6: =SUM('Monthly Operations'!BL12:BW12) -> -31161.287 | I6: =SUM('Monthly Operations'!BX12:CI12) -> -32096.126 | J6: =SUM('Monthly Operations'!CJ12:CU12) -> -33059.01 | K6: =SUM('Monthly Operations'!CV12:DG12) -> -34050.78 | L6: =SUM('Monthly Operations'!DH12:DS12) -> -35072.303
A7: Less: Collection Loss | C7: =SUM('Monthly Operations'!D13:O13) -> -2726.2667 | D7: =SUM('Monthly Operations'!P13:AA13) -> -3143.0793 | E7: =SUM('Monthly Operations'!AB13:AM13) -> -3279.4541 | F7: =SUM('Monthly Operations'!AN13:AY13) -> -3377.8377 | G7: =SUM('Monthly Operations'!AZ13:BK13) -> -3479.1728 | H7: =SUM('Monthly Operations'!BL13:BW13) -> -3583.548 | I7: =SUM('Monthly Operations'!BX13:CI13) -> -3691.0545 | J7: =SUM('Monthly Operations'!CJ13:CU13) -> -3801.7861 | K7: =SUM('Monthly Operations'!CV13:DG13) -> -3915.8397 | L7: =SUM('Monthly Operations'!DH13:DS13) -> -4033.3149
A8: Effective Gross Rental Revenue | C8: =SUM('Monthly Operations'!D14:O14) -> 269900.4 | D8: =SUM('Monthly Operations'!P14:AA14) -> 311164.85 | E8: =SUM('Monthly Operations'!AB14:AM14) -> 324665.95 | F8: =SUM('Monthly Operations'!AN14:AY14) -> 334405.93 | G8: =SUM('Monthly Operations'!AZ14:BK14) -> 344438.11 | H8: =SUM('Monthly Operations'!BL14:BW14) -> 354771.25 | I8: =SUM('Monthly Operations'!BX14:CI14) -> 365414.39 | J8: =SUM('Monthly Operations'!CJ14:CU14) -> 376376.82 | K8: =SUM('Monthly Operations'!CV14:DG14) -> 387668.13 | L8: =SUM('Monthly Operations'!DH14:DS14) -> 399298.17
A9: POH Home Revenue | C9: =SUM('Monthly Operations'!D15:O15) -> 33600 | D9: =SUM('Monthly Operations'!P15:AA15) -> 34608 | E9: =SUM('Monthly Operations'!AB15:AM15) -> 35646.24 | F9: =SUM('Monthly Operations'!AN15:AY15) -> 36715.627 | G9: =SUM('Monthly Operations'!AZ15:BK15) -> 37817.096 | H9: =SUM('Monthly Operations'!BL15:BW15) -> 38951.609 | I9: =SUM('Monthly Operations'!BX15:CI15) -> 40120.157 | J9: =SUM('Monthly Operations'!CJ15:CU15) -> 41323.762 | K9: =SUM('Monthly Operations'!CV15:DG15) -> 42563.475 | L9: =SUM('Monthly Operations'!DH15:DS15) -> 43840.379
A10: Other Income | C10: =SUM('Monthly Operations'!D16:O16) -> 15578.667 | D10: =SUM('Monthly Operations'!P16:AA16) -> 17873.267 | E10: =SUM('Monthly Operations'!AB16:AM16) -> 18558.24 | F10: =SUM('Monthly Operations'!AN16:AY16) -> 19022.196 | G10: =SUM('Monthly Operations'!AZ16:BK16) -> 19497.751 | H10: =SUM('Monthly Operations'!BL16:BW16) -> 19985.195 | I10: =SUM('Monthly Operations'!BX16:CI16) -> 20484.825 | J10: =SUM('Monthly Operations'!CJ16:CU16) -> 20996.945 | K10: =SUM('Monthly Operations'!CV16:DG16) -> 21521.869 | L10: =SUM('Monthly Operations'!DH16:DS16) -> 22059.916
A11: Utility Reimbursement | C11: =SUM('Monthly Operations'!D17:O17) -> 11684 | D11: =SUM('Monthly Operations'!P17:AA17) -> 13470.34 | E11: =SUM('Monthly Operations'!AB17:AM17) -> 14054.803 | F11: =SUM('Monthly Operations'!AN17:AY17) -> 14476.447 | G11: =SUM('Monthly Operations'!AZ17:BK17) -> 14910.741 | H11: =SUM('Monthly Operations'!BL17:BW17) -> 15358.063 | I11: =SUM('Monthly Operations'!BX17:CI17) -> 15818.805 | J11: =SUM('Monthly Operations'!CJ17:CU17) -> 16293.369 | K11: =SUM('Monthly Operations'!CV17:DG17) -> 16782.17 | L11: =SUM('Monthly Operations'!DH17:DS17) -> 17285.635
A12: EFFECTIVE GROSS REVENUE | C12: =SUM('Monthly Operations'!D18:O18) -> 330763.07 | D12: =SUM('Monthly Operations'!P18:AA18) -> 377116.46 | E12: =SUM('Monthly Operations'!AB18:AM18) -> 392925.24 | F12: =SUM('Monthly Operations'!AN18:AY18) -> 404620.2 | G12: =SUM('Monthly Operations'!AZ18:BK18) -> 416663.7 | H12: =SUM('Monthly Operations'!BL18:BW18) -> 429066.12 | I12: =SUM('Monthly Operations'!BX18:CI18) -> 441838.18 | J12: =SUM('Monthly Operations'!CJ18:CU18) -> 454990.9 | K12: =SUM('Monthly Operations'!CV18:DG18) -> 468535.64 | L12: =SUM('Monthly Operations'!DH18:DS18) -> 482484.1
A14: Occupancy % (avg, Yr-end) | C14: ='Monthly Operations'!O9 -> 0.86333333 | D14: ='Monthly Operations'!AA9 -> 0.92 | E14: ='Monthly Operations'!AM9 -> 0.92 | F14: ='Monthly Operations'!AY9 -> 0.92 | G14: ='Monthly Operations'!BK9 -> 0.92 | H14: ='Monthly Operations'!BW9 -> 0.92 | I14: ='Monthly Operations'!CI9 -> 0.92 | J14: ='Monthly Operations'!CU9 -> 0.92 | K14: ='Monthly Operations'!DG9 -> 0.92 | L14: ='Monthly Operations'!DS9 -> 0.92

Sheet Operating Expenses
A1: OPERATING EXPENSES — ANNUAL
A2: Fixed lines escalate at expense growth; management fee floats with revenue
C4: Year 1 | D4: Year 2 | E4: Year 3 | F4: Year 4 | G4: Year 5 | H4: Year 6 | I4: Year 7 | J4: Year 8 | K4: Year 9 | L4: Year 10
A5: Property Taxes | C5: =SUM('Monthly Operations'!D20:O20) -> -45000 | D5: =SUM('Monthly Operations'!P20:AA20) -> -46125 | E5: =SUM('Monthly Operations'!AB20:AM20) -> -47278.125 | F5: =SUM('Monthly Operations'!AN20:AY20) -> -48460.078 | G5: =SUM('Monthly Operations'!AZ20:BK20) -> -49671.58 | H5: =SUM('Monthly Operations'!BL20:BW20) -> -50913.37 | I5: =SUM('Monthly Operations'!BX20:CI20) -> -52186.204 | J5: =SUM('Monthly Operations'!CJ20:CU20) -> -53490.859 | K5: =SUM('Monthly Operations'!CV20:DG20) -> -54828.13 | L5: =SUM('Monthly Operations'!DH20:DS20) -> -56198.834
A6: Insurance | C6: =SUM('Monthly Operations'!D21:O21) -> -20000 | D6: =SUM('Monthly Operations'!P21:AA21) -> -20500 | E6: =SUM('Monthly Operations'!AB21:AM21) -> -21012.5 | F6: =SUM('Monthly Operations'!AN21:AY21) -> -21537.812 | G6: =SUM('Monthly Operations'!AZ21:BK21) -> -22076.258 | H6: =SUM('Monthly Operations'!BL21:BW21) -> -22628.164 | I6: =SUM('Monthly Operations'!BX21:CI21) -> -23193.868 | J6: =SUM('Monthly Operations'!CJ21:CU21) -> -23773.715 | K6: =SUM('Monthly Operations'!CV21:DG21) -> -24368.058 | L6: =SUM('Monthly Operations'!DH21:DS21) -> -24977.259
A7: Electricity | C7: =SUM('Monthly Operations'!D22:O22) -> -12000 | D7: =SUM('Monthly Operations'!P22:AA22) -> -12300 | E7: =SUM('Monthly Operations'!AB22:AM22) -> -12607.5 | F7: =SUM('Monthly Operations'!AN22:AY22) -> -12922.687 | G7: =SUM('Monthly Operations'!AZ22:BK22) -> -13245.755 | H7: =SUM('Monthly Operations'!BL22:BW22) -> -13576.899 | I7: =SUM('Monthly Operations'!BX22:CI22) -> -13916.321 | J7: =SUM('Monthly Operations'!CJ22:CU22) -> -14264.229 | K7: =SUM('Monthly Operations'!CV22:DG22) -> -14620.835 | L7: =SUM('Monthly Operations'!DH22:DS22) -> -14986.356
A8: Gas | C8: =SUM('Monthly Operations'!D23:O23) -> -3000 | D8: =SUM('Monthly Operations'!P23:AA23) -> -3075 | E8: =SUM('Monthly Operations'!AB23:AM23) -> -3151.875 | F8: =SUM('Monthly Operations'!AN23:AY23) -> -3230.6719 | G8: =SUM('Monthly Operations'!AZ23:BK23) -> -3311.4387 | H8: =SUM('Monthly Operations'!BL23:BW23) -> -3394.2246 | I8: =SUM('Monthly Operations'!BX23:CI23) -> -3479.0803 | J8: =SUM('Monthly Operations'!CJ23:CU23) -> -3566.0573 | K8: =SUM('Monthly Operations'!CV23:DG23) -> -3655.2087 | L8: =SUM('Monthly Operations'!DH23:DS23) -> -3746.5889
A9: Water | C9: =SUM('Monthly Operations'!D24:O24) -> -30000 | D9: =SUM('Monthly Operations'!P24:AA24) -> -30750 | E9: =SUM('Monthly Operations'!AB24:AM24) -> -31518.75 | F9: =SUM('Monthly Operations'!AN24:AY24) -> -32306.719 | G9: =SUM('Monthly Operations'!AZ24:BK24) -> -33114.387 | H9: =SUM('Monthly Operations'!BL24:BW24) -> -33942.246 | I9: =SUM('Monthly Operations'!BX24:CI24) -> -34790.803 | J9: =SUM('Monthly Operations'!CJ24:CU24) -> -35660.573 | K9: =SUM('Monthly Operations'!CV24:DG24) -> -36552.087 | L9: =SUM('Monthly Operations'!DH24:DS24) -> -37465.889
A10: Sewer | C10: =SUM('Monthly Operations'!D25:O25) -> -25000 | D10: =SUM('Monthly Operations'!P25:AA25) -> -25625 | E10: =SUM('Monthly Operations'!AB25:AM25) -> -26265.625 | F10: =SUM('Monthly Operations'!AN25:AY25) -> -26922.266 | G10: =SUM('Monthly Operations'!AZ25:BK25) -> -27595.322 | H10: =SUM('Monthly Operations'!BL25:BW25) -> -28285.205 | I10: =SUM('Monthly Operations'!BX25:CI25) -> -28992.335 | J10: =SUM('Monthly Operations'!CJ25:CU25) -> -29717.144 | K10: =SUM('Monthly Operations'!CV25:DG25) -> -30460.072 | L10: =SUM('Monthly Operations'!DH25:DS25) -> -31221.574
A11: Repairs & Maintenance | C11: =SUM('Monthly Operations'!D26:O26) -> -35000 | D11: =SUM('Monthly Operations'!P26:AA26) -> -35875 | E11: =SUM('Monthly Operations'!AB26:AM26) -> -36771.875 | F11: =SUM('Monthly Operations'!AN26:AY26) -> -37691.172 | G11: =SUM('Monthly Operations'!AZ26:BK26) -> -38633.451 | H11: =SUM('Monthly Operations'!BL26:BW26) -> -39599.287 | I11: =SUM('Monthly Operations'!BX26:CI26) -> -40589.27 | J11: =SUM('Monthly Operations'!CJ26:CU26) -> -41604.001 | K11: =SUM('Monthly Operations'!CV26:DG26) -> -42644.101 | L11: =SUM('Monthly Operations'!DH26:DS26) -> -43710.204
A12: POH Insurance | C12: =SUM('Monthly Operations'!D27:O27) -> -4000 | D12: =SUM('Monthly Operations'!P27:AA27) -> -4100 | E12: =SUM('Monthly Operations'!AB27:AM27) -> -4202.5 | F12: =SUM('Monthly Operations'!AN27:AY27) -> -4307.5625 | G12: =SUM('Monthly Operations'!AZ27:BK27) -> -4415.2516 | H12: =SUM('Monthly Operations'!BL27:BW27) -> -4525.6329 | I12: =SUM('Monthly Operations'!BX27:CI27) -> -4638.7737 | J12: =SUM('Monthly Operations'!CJ27:CU27) -> -4754.743 | K12: =SUM('Monthly Operations'!CV27:DG27) -> -4873.6116 | L12: =SUM('Monthly Operations'!DH27:DS27) -> -4995.4519
A13: POH Repairs | C13: =SUM('Monthly Operations'!D28:O28) -> -8000 | D13: =SUM('Monthly Operations'!P28:AA28) -> -8200 | E13: =SUM('Monthly Operations'!AB28:AM28) -> -8405 | F13: =SUM('Monthly Operations'!AN28:AY28) -> -8615.125 | G13: =SUM('Monthly Operations'!AZ28:BK28) -> -8830.5031 | H13: =SUM('Monthly Operations'!BL28:BW28) -> -9051.2657 | I13: =SUM('Monthly Operations'!BX28:CI28) -> -9277.5473 | J13: =SUM('Monthly Operations'!CJ28:CU28) -> -9509.486 | K13: =SUM('Monthly Operations'!CV28:DG28) -> -9747.2232 | L13: =SUM('Monthly Operations'!DH28:DS28) -> -9990.9038
A14: Turnover / Make-ready | C14: =SUM('Monthly Operations'!D29:O29) -> -6000 | D14: =SUM('Monthly Operations'!P29:AA29) -> -6150 | E14: =SUM('Monthly Operations'!AB29:AM29) -> -6303.75 | F14: =SUM('Monthly Operations'!AN29:AY29) -> -6461.3437 | G14: =SUM('Monthly Operations'!AZ29:BK29) -> -6622.8773 | H14: =SUM('Monthly Operations'!BL29:BW29) -> -6788.4493 | I14: =SUM('Monthly Operations'!BX29:CI29) -> -6958.1605 | J14: =SUM('Monthly Operations'!CJ29:CU29) -> -7132.1145 | K14: =SUM('Monthly Operations'!CV29:DG29) -> -7310.4174 | L14: =SUM('Monthly Operations'!DH29:DS29) -> -7493.1778
A15: Administrative | C15: =SUM('Monthly Operations'!D30:O30) -> -10000 | D15: =SUM('Monthly Operations'!P30:AA30) -> -10250 | E15: =SUM('Monthly Operations'!AB30:AM30) -> -10506.25 | F15: =SUM('Monthly Operations'!AN30:AY30) -> -10768.906 | G15: =SUM('Monthly Operations'!AZ30:BK30) -> -11038.129 | H15: =SUM('Monthly Operations'!BL30:BW30) -> -11314.082 | I15: =SUM('Monthly Operations'!BX30:CI30) -> -11596.934 | J15: =SUM('Monthly Operations'!CJ30:CU30) -> -11886.858 | K15: =SUM('Monthly Operations'!CV30:DG30) -> -12184.029 | L15: =SUM('Monthly Operations'!DH30:DS30) -> -12488.63
A16: Legal / Professional | C16: =SUM('Monthly Operations'!D31:O31) -> -5000 | D16: =SUM('Monthly Operations'!P31:AA31) -> -5125 | E16: =SUM('Monthly Operations'!AB31:AM31) -> -5253.125 | F16: =SUM('Monthly Operations'!AN31:AY31) -> -5384.4531 | G16: =SUM('Monthly Operations'!AZ31:BK31) -> -5519.0645 | H16: =SUM('Monthly Operations'!BL31:BW31) -> -5657.0411 | I16: =SUM('Monthly Operations'!BX31:CI31) -> -5798.4671 | J16: =SUM('Monthly Operations'!CJ31:CU31) -> -5943.4288 | K16: =SUM('Monthly Operations'!CV31:DG31) -> -6092.0145 | L16: =SUM('Monthly Operations'!DH31:DS31) -> -6244.3148
... A21: TOTAL OPERATING EXPENSES | C21: =SUM('Monthly Operations'!D36:O36) -> -245538.15 | D21: =SUM('Monthly Operations'!P36:AA36) -> -253580.82 | E21: =SUM('Monthly Operations'!AB36:AM36) -> -260239.39 | F21: =SUM('Monthly Operations'!AN36:AY36) -> -266838.96 | G21: =SUM('Monthly Operations'!AZ36:BK36) -> -273606.34 | H21: =SUM('Monthly Operations'!BL36:BW36) -> -280545.79 | I21: =SUM('Monthly Operations'!BX36:CI36) -> -287661.7 | J21: =SUM('Monthly Operations'!CJ36:CU36) -> -294958.58 | K21: =SUM('Monthly Operations'!CV36:DG36) -> -302441.05 | L21: =SUM('Monthly Operations'!DH36:DS36) -> -310113.83
A23: Expense Ratio (% of EGR) | C23: =IFERROR(-C21/Revenue!C12,0) -> 0.74233848 | D23: =IFERROR(-D21/Revenue!D12,0) -> 0.67242046 | E23: =IFERROR(-E21/Revenue!E12,0) -> 0.66231273 | F23: =IFERROR(-F21/Revenue!F12,0) -> 0.65948008 | G23: =IFERROR(-G21/Revenue!G12,0) -> 0.65665989 | H23: =IFERROR(-H21/Revenue!H12,0) -> 0.65385211 | I23: =IFERROR(-I21/Revenue!I12,0) -> 0.65105669 | J23: =IFERROR(-J21/Revenue!J12,0) -> 0.64827359 | ... L23: =IFERROR(-L21/Revenue!L12,0) -> 0.64274413

Sheet CapEx
A1: CAPITAL EXPENDITURES
A2: One-time infrastructure funded at close (Uses); ongoing replacement reserves run through NOI-after-CapEx
A4: Initial / One-time CapEx (funded at acquisition)
A5: Roads | B5: =Assumptions!$B$50 -> 40000
A6: Water/Sewer Infrastructure | B6: =Assumptions!$B$51 -> 60000
A7: Electrical | B7: =Assumptions!$B$52 -> 20000
A8: Common-Area Improvements | B8: =Assumptions!$B$53 -> 15000
A9: POH Renovations | B9: =Assumptions!$B$54 -> 30000
A10: Other CapEx | B10: =Assumptions!$B$55 -> 10000
A11: Total Initial CapEx | B11: =Assumptions!$B$56 -> 175000
A13: Ongoing Replacement Reserves (annual)
C14: Year 1 | D14: Year 2 | E14: Year 3 | F14: Year 4 | G14: Year 5 | H14: Year 6 | I14: Year 7 | J14: Year 8 | K14: Year 9 | L14: Year 10
A15: Replacement Reserves | C15: =SUM('Monthly Operations'!D41:O41) -> -4000 | D15: =SUM('Monthly Operations'!P41:AA41) -> -4100 | E15: =SUM('Monthly Operations'!AB41:AM41) -> -4202.5 | F15: =SUM('Monthly Operations'!AN41:AY41) -> -4307.5625 | G15: =SUM('Monthly Operations'!AZ41:BK41) -> -4415.2516 | H15: =SUM('Monthly Operations'!BL41:BW41) -> -4525.6329 | I15: =SUM('Monthly Operations'!BX41:CI41) -> -4638.7737 | J15: =SUM('Monthly Operations'!CJ41:CU41) -> -4754.743 | K15: =SUM('Monthly Operations'!CV41:DG41) -> -4873.6116 | L15: =SUM('Monthly Operations'!DH41:DS41) -> -4995.4519

Sheet Monthly Operations
A1: MONTHLY OPERATING MODEL
A2: 120-month engine — all revenue, expenses, NOI & CapEx. Annual sheets roll these up.
D3: =CEILING(D4/12,1) -> 1 | E3: =ROUNDUP(D4/12,0) -> 1 | F3: all3 formula canbe used
A4: Month # | D4: 1 | E4: 2 | F4: 3 | G4: 4 | H4: 5 | I4: 6 | J4: 7 | K4: 8 | L4: 9 | M4: 10 | N4: 11 | O4: 12 | P4: 13 | Q4: 14 | R4: 15 | S4: 16 | T4: 17 | U4: 18 | V4: 19 | W4: 20 | X4: 21 | Y4: 22 | Z4: 23 | AA4: 24 | AB4: 25 | AC4: 26 | AD4: 27 | AE4: 28 | AF4: 29 | AG4: 30 | AH4: 31 | AI4: 32 | AJ4: 33 | AK4: 34 | AL4: 35 | AM4: 36 | AN4: 37 | AO4: 38 | AP4: 39 | AQ4: 40 | AR4: 41 | AS4: 42 | AT4: 43 | AU4: 44 | AV4: 45 | AW4: 46 | AX4: 47 | AY4: 48 | AZ4: 49 | BA4: 50 | BB4: 51 | BC4: 52 | BD4: 53 | BE4: 54 | BF4: 55 | BG4: 56 | BH4: 57 | BI4: 58 | BJ4: 59 | BK4: 60 | BL4: 61 | BM4: 62 | BN4: 63 | BO4: 64 | BP4: 65 | BQ4: 66 | BR4: 67 | BS4: 68 | BT4: 69 | BU4: 70 | BV4: 71 | BW4: 72 | BX4: 73 | BY4: 74 | BZ4: 75 | CA4: 76 | CB4: 77 | CC4: 78 | CD4: 79 | CE4: 80 | CF4: 81 | CG4: 82 | CH4: 83 | CI4: 84 | CJ4: 85 | CK4: 86 | CL4: 87 | CM4: 88 | CN4: 89 | CO4: 90 | CP4: 91 | CQ4: 92 | CR4: 93 | CS4: 94 | CT4: 95 | CU4: 96 | CV4: 97 | CW4: 98 | CX4: 99 | CY4: 100 | CZ4: 101 | DA4: 102 | DB4: 103 | DC4: 104 | DD4: 105 | DE4: 106 | DF4: 107 | DG4: 108 | DH4: 109 | DI4: 110 | DJ4: 111 | DK4: 112 | DL4: 113 | DM4: 114 | DN4: 115 | DO4: 116 | DP4: 117 | DQ4: 118 | DR4: 119 | DS4: 120
A5: Year | D5: =INT((D4-1)/12)+1 -> 1 | E5: =INT((E4-1)/12)+1 -> 1 | F5: =INT((F4-1)/12)+1 -> 1 | G5: =INT((G4-1)/12)+1 -> 1 | H5: =INT((H4-1)/12)+1 -> 1 | I5: =INT((I4-1)/12)+1 -> 1 | J5: =INT((J4-1)/12)+1 -> 1 | K5: =INT((K4-1)/12)+1 -> 1 | ... DS5: =INT((DS4-1)/12)+1 -> 10
A6: Period | D6: =EDATE(Assumptions!$B$15,D4-1) -> 46023 | E6: =EDATE(Assumptions!$B$15,E4-1) -> 46054 | F6: =EDATE(Assumptions!$B$15,F4-1) -> 46082 | G6: =EDATE(Assumptions!$B$15,G4-1) -> 46113 | H6: =EDATE(Assumptions!$B$15,H4-1) -> 46143 | I6: =EDATE(Assumptions!$B$15,I4-1) -> 46174 | J6: =EDATE(Assumptions!$B$15,J4-1) -> 46204 | K6: =EDATE(Assumptions!$B$15,K4-1) -> 46235 | ... DS6: =EDATE(Assumptions!$B$15,DS4-1) -> 49644
A8: Occupied Pads | D8: =MIN(Assumptions!$B$9*Assumptions!$B$16,Assumptions!$B$17+(Assumptions!$B$9*Assumptions!$B$16-Assumptions!$B$17)*MIN(D4,Assumptions!$B$29)/Assumptions!$B$29) -> 60.755556 | E8: =MIN(Assumptions!$B$9*Assumptions!$B$16,Assumptions!$B$17+(Assumptions!$B$9*Assumptions!$B$16-Assumptions!$B$17)*MIN(E4,Assumptions!$B$29)/Assumptions!$B$29) -> 61.511111 | F8: =MIN(Assumptions!$B$9*Assumptions!$B$16,Assumptions!$B$17+(Assumptions!$B$9*Assumptions!$B$16-Assumptions!$B$17)*MIN(F4,Assumptions!$B$29)/Assumptions!$B$29) -> 62.266667 | G8: =MIN(Assumptions!$B$9*Assumptions!$B$16,Assumptions!$B$17+(Assumptions!$B$9*Assumptions!$B$16-Assumptions!$B$17)*MIN(G4,Assumptions!$B$29)/Assumptions!$B$29) -> 63.022222 | H8: =MIN(Assumptions!$B$9*Assumptions!$B$16,Assumptions!$B$17+(Assumptions!$B$9*Assumptions!$B$16-Assumptions!$B$17)*MIN(H4,Assumptions!$B$29)/Assumptions!$B$29) -> 63.777778 | I8: =MIN(Assumptions!$B$9*Assumptions!$B$16,Assumptions!$B$17+(Assumptions!$B$9*Assumptions!$B$16-Assumptions!$B$17)*MIN(I4,Assumptions!$B$29)/Assumptions!$B$29) -> 64.533333 | J8: =MIN(Assumptions!$B$9*Assumptions!$B$16,Assumptions!$B$17+(Assumptions!$B$9*Assumptions!$B$16-Assumptions!$B$17)*MIN(J4,Assumptions!$B$29)/Assumptions!$B$29) -> 65.288889 | K8: =MIN(Assumptions!$B$9*Assumptions!$B$16,Assumptions!$B$17+(Assumptions!$B$9*Assumptions!$B$16-Assumptions!$B$17)*MIN(K4,Assumptions!$B$29)/Assumptions!$B$29) -> 66.044444 | ... DS8: =MIN(Assumptions!$B$9*Assumptions!$B$16,Assumptions!$B$17+(Assumptions!$B$9*Assumptions!$B$16-Assumptions!$B$17)*MIN(DS4,Assumptions!$B$29)/Assumptions!$B$29) -> 73.6
A9: Occupancy % | D9: =D8/Assumptions!$B$16 -> 0.75944444 | E9: =E8/Assumptions!$B$16 -> 0.76888889 | F9: =F8/Assumptions!$B$16 -> 0.77833333 | G9: =G8/Assumptions!$B$16 -> 0.78777778 | H9: =H8/Assumptions!$B$16 -> 0.79722222 | I9: =I8/Assumptions!$B$16 -> 0.80666667 | J9: =J8/Assumptions!$B$16 -> 0.81611111 | K9: =K8/Assumptions!$B$16 -> 0.82555556 | ... DS9: =DS8/Assumptions!$B$16 -> 0.92
A10: Lot Rent / Pad | D10: =Assumptions!$B$23*(1+Assumptions!$B$10)^(D5-1) -> 350 | E10: =Assumptions!$B$23*(1+Assumptions!$B$10)^(E5-1) -> 350 | F10: =Assumptions!$B$23*(1+Assumptions!$B$10)^(F5-1) -> 350 | G10: =Assumptions!$B$23*(1+Assumptions!$B$10)^(G5-1) -> 350 | H10: =Assumptions!$B$23*(1+Assumptions!$B$10)^(H5-1) -> 350 | I10: =Assumptions!$B$23*(1+Assumptions!$B$10)^(I5-1) -> 350 | J10: =Assumptions!$B$23*(1+Assumptions!$B$10)^(J5-1) -> 350 | K10: =Assumptions!$B$23*(1+Assumptions!$B$10)^(K5-1) -> 350 | ... DS10: =Assumptions!$B$23*(1+Assumptions!$B$10)^(DS5-1) -> 456.67061
A11: Potential Gross Rent | D11: =Assumptions!$B$16*D10 -> 28000 | E11: =Assumptions!$B$16*E10 -> 28000 | F11: =Assumptions!$B$16*F10 -> 28000 | G11: =Assumptions!$B$16*G10 -> 28000 | H11: =Assumptions!$B$16*H10 -> 28000 | I11: =Assumptions!$B$16*I10 -> 28000 | J11: =Assumptions!$B$16*J10 -> 28000 | K11: =Assumptions!$B$16*K10 -> 28000 | ... DS11: =Assumptions!$B$16*DS10 -> 36533.649
A12: Less: Vacancy Loss | D12: =-(Assumptions!$B$16-D8)*D10 -> -6735.5556 | E12: =-(Assumptions!$B$16-E8)*E10 -> -6471.1111 | F12: =-(Assumptions!$B$16-F8)*F10 -> -6206.6667 | G12: =-(Assumptions!$B$16-G8)*G10 -> -5942.2222 | H12: =-(Assumptions!$B$16-H8)*H10 -> -5677.7778 | I12: =-(Assumptions!$B$16-I8)*I10 -> -5413.3333 | J12: =-(Assumptions!$B$16-J8)*J10 -> -5148.8889 | K12: =-(Assumptions!$B$16-K8)*K10 -> -4884.4444 | ... DS12: =-(Assumptions!$B$16-DS8)*DS10 -> -2922.6919
A13: Less: Collection Loss | D13: =-Assumptions!$B$28*(D11+D12) -> -212.64444 | E13: =-Assumptions!$B$28*(E11+E12) -> -215.28889 | F13: =-Assumptions!$B$28*(F11+F12) -> -217.93333 | G13: =-Assumptions!$B$28*(G11+G12) -> -220.57778 | H13: =-Assumptions!$B$28*(H11+H12) -> -223.22222 | I13: =-Assumptions!$B$28*(I11+I12) -> -225.86667 | J13: =-Assumptions!$B$28*(J11+J12) -> -228.51111 | K13: =-Assumptions!$B$28*(K11+K12) -> -231.15556 | ... DS13: =-Assumptions!$B$28*(DS11+DS12) -> -336.10957
A14: Effective Gross Rental Rev | D14: =D11+D12+D13 -> 21051.8 | E14: =E11+E12+E13 -> 21313.6 | F14: =F11+F12+F13 -> 21575.4 | G14: =G11+G12+G13 -> 21837.2 | H14: =H11+H12+H13 -> 22099 | I14: =I11+I12+I13 -> 22360.8 | J14: =J11+J12+J13 -> 22622.6 | K14: =K11+K12+K13 -> 22884.4 | ... DS14: =DS11+DS12+DS13 -> 33274.848
A15: POH Home Revenue | D15: =Assumptions!$B$20*Assumptions!$B$25*(1+Assumptions!$B$10)^(D5-1) -> 2800 | E15: =Assumptions!$B$20*Assumptions!$B$25*(1+Assumptions!$B$10)^(E5-1) -> 2800 | F15: =Assumptions!$B$20*Assumptions!$B$25*(1+Assumptions!$B$10)^(F5-1) -> 2800 | G15: =Assumptions!$B$20*Assumptions!$B$25*(1+Assumptions!$B$10)^(G5-1) -> 2800 | H15: =Assumptions!$B$20*Assumptions!$B$25*(1+Assumptions!$B$10)^(H5-1) -> 2800 | I15: =Assumptions!$B$20*Assumptions!$B$25*(1+Assumptions!$B$10)^(I5-1) -> 2800 | J15: =Assumptions!$B$20*Assumptions!$B$25*(1+Assumptions!$B$10)^(J5-1) -> 2800 | K15: =Assumptions!$B$20*Assumptions!$B$25*(1+Assumptions!$B$10)^(K5-1) -> 2800 | ... DS15: =Assumptions!$B$20*Assumptions!$B$25*(1+Assumptions!$B$10)^(DS5-1) -> 3653.3649
A16: Other Income | D16: =D8*Assumptions!$B$26*(1+Assumptions!$B$30)^(D5-1) -> 1215.1111 | E16: =E8*Assumptions!$B$26*(1+Assumptions!$B$30)^(E5-1) -> 1230.2222 | F16: =F8*Assumptions!$B$26*(1+Assumptions!$B$30)^(F5-1) -> 1245.3333 | G16: =G8*Assumptions!$B$26*(1+Assumptions!$B$30)^(G5-1) -> 1260.4444 | H16: =H8*Assumptions!$B$26*(1+Assumptions!$B$30)^(H5-1) -> 1275.5556 | I16: =I8*Assumptions!$B$26*(1+Assumptions!$B$30)^(I5-1) -> 1290.6667 | J16: =J8*Assumptions!$B$26*(1+Assumptions!$B$30)^(J5-1) -> 1305.7778 | K16: =K8*Assumptions!$B$26*(1+Assumptions!$B$30)^(K5-1) -> 1320.8889 | ... DS16: =DS8*Assumptions!$B$26*(1+Assumptions!$B$30)^(DS5-1) -> 1838.3263
A17: Utility Reimbursement | D17: =D8*Assumptions!$B$27*(1+Assumptions!$B$10)^(D5-1) -> 911.33333 | E17: =E8*Assumptions!$B$27*(1+Assumptions!$B$10)^(E5-1) -> 922.66667 | F17: =F8*Assumptions!$B$27*(1+Assumptions!$B$10)^(F5-1) -> 934 | G17: =G8*Assumptions!$B$27*(1+Assumptions!$B$10)^(G5-1) -> 945.33333 | H17: =H8*Assumptions!$B$27*(1+Assumptions!$B$10)^(H5-1) -> 956.66667 | I17: =I8*Assumptions!$B$27*(1+Assumptions!$B$10)^(I5-1) -> 968 | J17: =J8*Assumptions!$B$27*(1+Assumptions!$B$10)^(J5-1) -> 979.33333 | K17: =K8*Assumptions!$B$27*(1+Assumptions!$B$10)^(K5-1) -> 990.66667 | ... DS17: =DS8*Assumptions!$B$27*(1+Assumptions!$B$10)^(DS5-1) -> 1440.4696
A18: EFFECTIVE GROSS REVENUE | D18: =SUM(D14:D17) -> 25978.244 | E18: =SUM(E14:E17) -> 26266.489 | F18: =SUM(F14:F17) -> 26554.733 | G18: =SUM(G14:G17) -> 26842.978 | H18: =SUM(H14:H17) -> 27131.222 | I18: =SUM(I14:I17) -> 27419.467 | J18: =SUM(J14:J17) -> 27707.711 | K18: =SUM(K14:K17) -> 27995.956 | ... DS18: =SUM(DS14:DS17) -> 40207.008
A19: OPERATING EXPENSES
A20: Property Taxes | D20: =-Assumptions!$B$32/12*(1+Assumptions!$B$11)^(D5-1) -> -3750 | E20: =-Assumptions!$B$32/12*(1+Assumptions!$B$11)^(E5-1) -> -3750 | F20: =-Assumptions!$B$32/12*(1+Assumptions!$B$11)^(F5-1) -> -3750 | G20: =-Assumptions!$B$32/12*(1+Assumptions!$B$11)^(G5-1) -> -3750 | H20: =-Assumptions!$B$32/12*(1+Assumptions!$B$11)^(H5-1) -> -3750 | I20: =-Assumptions!$B$32/12*(1+Assumptions!$B$11)^(I5-1) -> -3750 | J20: =-Assumptions!$B$32/12*(1+Assumptions!$B$11)^(J5-1) -> -3750 | K20: =-Assumptions!$B$32/12*(1+Assumptions!$B$11)^(K5-1) -> -3750 | ... DS20: =-Assumptions!$B$32/12*(1+Assumptions!$B$11)^(DS5-1) -> -4683.2361
A21: Insurance | D21: =-Assumptions!$B$33/12*(1+Assumptions!$B$11)^(D5-1) -> -1666.6667 | E21: =-Assumptions!$B$33/12*(1+Assumptions!$B$11)^(E5-1) -> -1666.6667 | F21: =-Assumptions!$B$33/12*(1+Assumptions!$B$11)^(F5-1) -> -1666.6667 | G21: =-Assumptions!$B$33/12*(1+Assumptions!$B$11)^(G5-1) -> -1666.6667 | H21: =-Assumptions!$B$33/12*(1+Assumptions!$B$11)^(H5-1) -> -1666.6667 | I21: =-Assumptions!$B$33/12*(1+Assumptions!$B$11)^(I5-1) -> -1666.6667 | J21: =-Assumptions!$B$33/12*(1+Assumptions!$B$11)^(J5-1) -> -1666.6667 | K21: =-Assumptions!$B$33/12*(1+Assumptions!$B$11)^(K5-1) -> -1666.6667 | ... DS21: =-Assumptions!$B$33/12*(1+Assumptions!$B$11)^(DS5-1) -> -2081.4383
A22: Electricity | D22: =-Assumptions!$B$34/12*(1+Assumptions!$B$11)^(D5-1) -> -1000 | E22: =-Assumptions!$B$34/12*(1+Assumptions!$B$11)^(E5-1) -> -1000 | F22: =-Assumptions!$B$34/12*(1+Assumptions!$B$11)^(F5-1) -> -1000 | G22: =-Assumptions!$B$34/12*(1+Assumptions!$B$11)^(G5-1) -> -1000 | H22: =-Assumptions!$B$34/12*(1+Assumptions!$B$11)^(H5-1) -> -1000 | I22: =-Assumptions!$B$34/12*(1+Assumptions!$B$11)^(I5-1) -> -1000 | J22: =-Assumptions!$B$34/12*(1+Assumptions!$B$11)^(J5-1) -> -1000 | K22: =-Assumptions!$B$34/12*(1+Assumptions!$B$11)^(K5-1) -> -1000 | ... DS22: =-Assumptions!$B$34/12*(1+Assumptions!$B$11)^(DS5-1) -> -1248.863
A23: Gas | D23: =-Assumptions!$B$35/12*(1+Assumptions!$B$11)^(D5-1) -> -250 | E23: =-Assumptions!$B$35/12*(1+Assumptions!$B$11)^(E5-1) -> -250 | F23: =-Assumptions!$B$35/12*(1+Assumptions!$B$11)^(F5-1) -> -250 | G23: =-Assumptions!$B$35/12*(1+Assumptions!$B$11)^(G5-1) -> -250 | H23: =-Assumptions!$B$35/12*(1+Assumptions!$B$11)^(H5-1) -> -250 | I23: =-Assumptions!$B$35/12*(1+Assumptions!$B$11)^(I5-1) -> -250 | J23: =-Assumptions!$B$35/12*(1+Assumptions!$B$11)^(J5-1) -> -250 | K23: =-Assumptions!$B$35/12*(1+Assumptions!$B$11)^(K5-1) -> -250 | ... DS23: =-Assumptions!$B$35/12*(1+Assumptions!$B$11)^(DS5-1) -> -312.21574
A24: Water | D24: =-Assumptions!$B$36/12*(1+Assumptions!$B$11)^(D5-1) -> -2500 | E24: =-Assumptions!$B$36/12*(1+Assumptions!$B$11)^(E5-1) -> -2500 | F24: =-Assumptions!$B$36/12*(1+Assumptions!$B$11)^(F5-1) -> -2500 | G24: =-Assumptions!$B$36/12*(1+Assumptions!$B$11)^(G5-1) -> -2500 | H24: =-Assumptions!$B$36/12*(1+Assumptions!$B$11)^(H5-1) -> -2500 | I24: =-Assumptions!$B$36/12*(1+Assumptions!$B$11)^(I5-1) -> -2500 | J24: =-Assumptions!$B$36/12*(1+Assumptions!$B$11)^(J5-1) -> -2500 | K24: =-Assumptions!$B$36/12*(1+Assumptions!$B$11)^(K5-1) -> -2500 | ... DS24: =-Assumptions!$B$36/12*(1+Assumptions!$B$11)^(DS5-1) -> -3122.1574
A25: Sewer | D25: =-Assumptions!$B$37/12*(1+Assumptions!$B$11)^(D5-1) -> -2083.3333 | E25: =-Assumptions!$B$37/12*(1+Assumptions!$B$11)^(E5-1) -> -2083.3333 | F25: =-Assumptions!$B$37/12*(1+Assumptions!$B$11)^(F5-1) -> -2083.3333 | G25: =-Assumptions!$B$37/12*(1+Assumptions!$B$11)^(G5-1) -> -2083.3333 | H25: =-Assumptions!$B$37/12*(1+Assumptions!$B$11)^(H5-1) -> -2083.3333 | I25: =-Assumptions!$B$37/12*(1+Assumptions!$B$11)^(I5-1) -> -2083.3333 | J25: =-Assumptions!$B$37/12*(1+Assumptions!$B$11)^(J5-1) -> -2083.3333 | K25: =-Assumptions!$B$37/12*(1+Assumptions!$B$11)^(K5-1) -> -2083.3333 | ... DS25: =-Assumptions!$B$37/12*(1+Assumptions!$B$11)^(DS5-1) -> -2601.7979
A26: Repairs & Maintenance | D26: =-Assumptions!$B$38/12*(1+Assumptions!$B$11)^(D5-1) -> -2916.6667 | E26: =-Assumptions!$B$38/12*(1+Assumptions!$B$11)^(E5-1) -> -2916.6667 | F26: =-Assumptions!$B$38/12*(1+Assumptions!$B$11)^(F5-1) -> -2916.6667 | G26: =-Assumptions!$B$38/12*(1+Assumptions!$B$11)^(G5-1) -> -2916.6667 | H26: =-Assumptions!$B$38/12*(1+Assumptions!$B$11)^(H5-1) -> -2916.6667 | I26: =-Assumptions!$B$38/12*(1+Assumptions!$B$11)^(I5-1) -> -2916.6667 | J26: =-Assumptions!$B$38/12*(1+Assumptions!$B$11)^(J5-1) -> -2916.6667 | K26: =-Assumptions!$B$38/12*(1+Assumptions!$B$11)^(K5-1) -> -2916.6667 | ... DS26: =-Assumptions!$B$38/12*(1+Assumptions!$B$11)^(DS5-1) -> -3642.517
A27: POH Insurance | D27: =-Assumptions!$B$39/12*(1+Assumptions!$B$11)^(D5-1) -> -333.33333 | E27: =-Assumptions!$B$39/12*(1+Assumptions!$B$11)^(E5-1) -> -333.33333 | F27: =-Assumptions!$B$39/12*(1+Assumptions!$B$11)^(F5-1) -> -333.33333 | G27: =-Assumptions!$B$39/12*(1+Assumptions!$B$11)^(G5-1) -> -333.33333 | H27: =-Assumptions!$B$39/12*(1+Assumptions!$B$11)^(H5-1) -> -333.33333 | I27: =-Assumptions!$B$39/12*(1+Assumptions!$B$11)^(I5-1) -> -333.33333 | J27: =-Assumptions!$B$39/12*(1+Assumptions!$B$11)^(J5-1) -> -333.33333 | K27: =-Assumptions!$B$39/12*(1+Assumptions!$B$11)^(K5-1) -> -333.33333 | ... DS27: =-Assumptions!$B$39/12*(1+Assumptions!$B$11)^(DS5-1) -> -416.28766
A28: POH Repairs | D28: =-Assumptions!$B$40/12*(1+Assumptions!$B$11)^(D5-1) -> -666.66667 | E28: =-Assumptions!$B$40/12*(1+Assumptions!$B$11)^(E5-1) -> -666.66667 | F28: =-Assumptions!$B$40/12*(1+Assumptions!$B$11)^(F5-1) -> -666.66667 | G28: =-Assumptions!$B$40/12*(1+Assumptions!$B$11)^(G5-1) -> -666.66667 | H28: =-Assumptions!$B$40/12*(1+Assumptions!$B$11)^(H5-1) -> -666.66667 | I28: =-Assumptions!$B$40/12*(1+Assumptions!$B$11)^(I5-1) -> -666.66667 | J28: =-Assumptions!$B$40/12*(1+Assumptions!$B$11)^(J5-1) -> -666.66667 | K28: =-Assumptions!$B$40/12*(1+Assumptions!$B$11)^(K5-1) -> -666.66667 | ... DS28: =-Assumptions!$B$40/12*(1+Assumptions!$B$11)^(DS5-1) -> -832.57531
A29: Turnover / Make-ready | D29: =-Assumptions!$B$41/12*(1+Assumptions!$B$11)^(D5-1) -> -500 | E29: =-Assumptions!$B$41/12*(1+Assumptions!$B$11)^(E5-1) -> -500 | F29: =-Assumptions!$B$41/12*(1+Assumptions!$B$11)^(F5-1) -> -500 | G29: =-Assumptions!$B$41/12*(1+Assumptions!$B$11)^(G5-1) -> -500 | H29: =-Assumptions!$B$41/12*(1+Assumptions!$B$11)^(H5-1) -> -500 | I29: =-Assumptions!$B$41/12*(1+Assumptions!$B$11)^(I5-1) -> -500 | J29: =-Assumptions!$B$41/12*(1+Assumptions!$B$11)^(J5-1) -> -500 | K29: =-Assumptions!$B$41/12*(1+Assumptions!$B$11)^(K5-1) -> -500 | ... DS29: =-Assumptions!$B$41/12*(1+Assumptions!$B$11)^(DS5-1) -> -624.43148
A30: Administrative | D30: =-Assumptions!$B$42/12*(1+Assumptions!$B$11)^(D5-1) -> -833.33333 | E30: =-Assumptions!$B$42/12*(1+Assumptions!$B$11)^(E5-1) -> -833.33333 | F30: =-Assumptions!$B$42/12*(1+Assumptions!$B$11)^(F5-1) -> -833.33333 | G30: =-Assumptions!$B$42/12*(1+Assumptions!$B$11)^(G5-1) -> -833.33333 | H30: =-Assumptions!$B$42/12*(1+Assumptions!$B$11)^(H5-1) -> -833.33333 | I30: =-Assumptions!$B$42/12*(1+Assumptions!$B$11)^(I5-1) -> -833.33333 | J30: =-Assumptions!$B$42/12*(1+Assumptions!$B$11)^(J5-1) -> -833.33333 | K30: =-Assumptions!$B$42/12*(1+Assumptions!$B$11)^(K5-1) -> -833.33333 | ... DS30: =-Assumptions!$B$42/12*(1+Assumptions!$B$11)^(DS5-1) -> -1040.7191
A31: Legal / Professional | D31: =-Assumptions!$B$43/12*(1+Assumptions!$B$11)^(D5-1) -> -416.66667 | E31: =-Assumptions!$B$43/12*(1+Assumptions!$B$11)^(E5-1) -> -416.66667 | F31: =-Assumptions!$B$43/12*(1+Assumptions!$B$11)^(F5-1) -> -416.66667 | G31: =-Assumptions!$B$43/12*(1+Assumptions!$B$11)^(G5-1) -> -416.66667 | H31: =-Assumptions!$B$43/12*(1+Assumptions!$B$11)^(H5-1) -> -416.66667 | I31: =-Assumptions!$B$43/12*(1+Assumptions!$B$11)^(I5-1) -> -416.66667 | J31: =-Assumptions!$B$43/12*(1+Assumptions!$B$11)^(J5-1) -> -416.66667 | K31: =-Assumptions!$B$43/12*(1+Assumptions!$B$11)^(K5-1) -> -416.66667 | ... DS31: =-Assumptions!$B$43/12*(1+Assumptions!$B$11)^(DS5-1) -> -520.35957
A32: Landscaping | D32: =-Assumptions!$B$44/12*(1+Assumptions!$B$11)^(D5-1) -> -666.66667 | E32: =-Assumptions!$B$44/12*(1+Assumptions!$B$11)^(E5-1) -> -666.66667 | F32: =-Assumptions!$B$44/12*(1+Assumptions!$B$11)^(F5-1) -> -666.66667 | G32: =-Assumptions!$B$44/12*(1+Assumptions!$B$11)^(G5-1) -> -666.66667 | H32: =-Assumptions!$B$44/12*(1+Assumptions!$B$11)^(H5-1) -> -666.66667 | I32: =-Assumptions!$B$44/12*(1+Assumptions!$B$11)^(I5-1) -> -666.66667 | J32: =-Assumptions!$B$44/12*(1+Assumptions!$B$11)^(J5-1) -> -666.66667 | K32: =-Assumptions!$B$44/12*(1+Assumptions!$B$11)^(K5-1) -> -666.66667 | ... DS32: =-Assumptions!$B$44/12*(1+Assumptions!$B$11)^(DS5-1) -> -832.57531
A33: Trash | D33: =-Assumptions!$B$45/12*(1+Assumptions!$B$11)^(D5-1) -> -1000 | E33: =-Assumptions!$B$45/12*(1+Assumptions!$B$11)^(E5-1) -> -1000 | F33: =-Assumptions!$B$45/12*(1+Assumptions!$B$11)^(F5-1) -> -1000 | G33: =-Assumptions!$B$45/12*(1+Assumptions!$B$11)^(G5-1) -> -1000 | H33: =-Assumptions!$B$45/12*(1+Assumptions!$B$11)^(H5-1) -> -1000 | I33: =-Assumptions!$B$45/12*(1+Assumptions!$B$11)^(I5-1) -> -1000 | J33: =-Assumptions!$B$45/12*(1+Assumptions!$B$11)^(J5-1) -> -1000 | K33: =-Assumptions!$B$45/12*(1+Assumptions!$B$11)^(K5-1) -> -1000 | ... DS33: =-Assumptions!$B$45/12*(1+Assumptions!$B$11)^(DS5-1) -> -1248.863
A34: Other Operating | D34: =-Assumptions!$B$46/12*(1+Assumptions!$B$11)^(D5-1) -> -500 | E34: =-Assumptions!$B$46/12*(1+Assumptions!$B$11)^(E5-1) -> -500 | F34: =-Assumptions!$B$46/12*(1+Assumptions!$B$11)^(F5-1) -> -500 | G34: =-Assumptions!$B$46/12*(1+Assumptions!$B$11)^(G5-1) -> -500 | H34: =-Assumptions!$B$46/12*(1+Assumptions!$B$11)^(H5-1) -> -500 | I34: =-Assumptions!$B$46/12*(1+Assumptions!$B$11)^(I5-1) -> -500 | J34: =-Assumptions!$B$46/12*(1+Assumptions!$B$11)^(J5-1) -> -500 | K34: =-Assumptions!$B$46/12*(1+Assumptions!$B$11)^(K5-1) -> -500 | ... DS34: =-Assumptions!$B$46/12*(1+Assumptions!$B$11)^(DS5-1) -> -624.43148
A35: Management Fee | D35: =-Assumptions!$B$47*D18 -> -1298.9122 | E35: =-Assumptions!$B$47*E18 -> -1313.3244 | F35: =-Assumptions!$B$47*F18 -> -1327.7367 | G35: =-Assumptions!$B$47*G18 -> -1342.1489 | H35: =-Assumptions!$B$47*H18 -> -1356.5611 | I35: =-Assumptions!$B$47*I18 -> -1370.9733 | J35: =-Assumptions!$B$47*J18 -> -1385.3856 | K35: =-Assumptions!$B$47*K18 -> -1399.7978 | ... DS35: =-Assumptions!$B$47*DS18 -> -2010.3504
A36: TOTAL OPERATING EXPENSES | D36: =SUM(D20:D35) -> -20382.246 | E36: =SUM(E20:E35) -> -20396.658 | F36: =SUM(F20:F35) -> -20411.07 | G36: =SUM(G20:G35) -> -20425.482 | H36: =SUM(H20:H35) -> -20439.894 | I36: =SUM(I20:I35) -> -20454.307 | J36: =SUM(J20:J35) -> -20468.719 | K36: =SUM(K20:K35) -> -20483.131 | ... DS36: =SUM(DS20:DS35) -> -25842.819
A38: NET OPERATING INCOME | B38: NOI | D38: =D18+D36 -> 5595.9989 | E38: =E18+E36 -> 5869.8311 | F38: =F18+F36 -> 6143.6633 | G38: =G18+G36 -> 6417.4956 | H38: =H18+H36 -> 6691.3278 | I38: =I18+I36 -> 6965.16 | J38: =J18+J36 -> 7238.9922 | K38: =K18+K36 -> 7512.8244 | ... DS38: =DS18+DS36 -> 14364.19
A39: NOI Margin | D39: =IFERROR(D38/D18,0) -> 0.21541097 | E39: =IFERROR(E38/E18,0) -> 0.22347224 | F39: =IFERROR(F38/F18,0) -> 0.2313585 | G39: =IFERROR(G38/G18,0) -> 0.2390754 | H39: =IFERROR(H38/H18,0) -> 0.24662832 | I39: =IFERROR(I38/I18,0) -> 0.25402245 | J39: =IFERROR(J38/J18,0) -> 0.26126273 | K39: =IFERROR(K38/K18,0) -> 0.26835392 | ... DS39: =IFERROR(DS38/DS18,0) -> 0.35725587
A41: Capital Expenditures (reserves) | D41: =-Assumptions!$B$49/12*Assumptions!$B$16*(1+Assumptions!$B$11)^(D5-1) -> -333.33333 | E41: =-Assumptions!$B$49/12*Assumptions!$B$16*(1+Assumptions!$B$11)^(E5-1) -> -333.33333 | F41: =-Assumptions!$B$49/12*Assumptions!$B$16*(1+Assumptions!$B$11)^(F5-1) -> -333.33333 | G41: =-Assumptions!$B$49/12*Assumptions!$B$16*(1+Assumptions!$B$11)^(G5-1) -> -333.33333 | H41: =-Assumptions!$B$49/12*Assumptions!$B$16*(1+Assumptions!$B$11)^(H5-1) -> -333.33333 | I41: =-Assumptions!$B$49/12*Assumptions!$B$16*(1+Assumptions!$B$11)^(I5-1) -> -333.33333 | J41: =-Assumptions!$B$49/12*Assumptions!$B$16*(1+Assumptions!$B$11)^(J5-1) -> -333.33333 | K41: =-Assumptions!$B$49/12*Assumptions!$B$16*(1+Assumptions!$B$11)^(K5-1) -> -333.33333 | ... DS41: =-Assumptions!$B$49/12*Assumptions!$B$16*(1+Assumptions!$B$11)^(DS5-1) -> -416.28766
A42: NOI AFTER CAPEX | D42: =D38+D41 -> 5262.6656 | E42: =E38+E41 -> 5536.4978 | F42: =F38+F41 -> 5810.33 | G42: =G38+G41 -> 6084.1622 | H42: =H38+H41 -> 6357.9944 | I42: =I38+I41 -> 6631.8267 | J42: =J38+J41 -> 6905.6589 | K42: =K38+K41 -> 7179.4911 | ... DS42: =DS38+DS41 -> 13947.902
A44: Fwd 12-mo NOI (for valn) | D44: =SUM(E38:P38) -> 88866.143 | E44: =SUM(F38:Q38) -> 92515.516 | F44: =SUM(G38:R38) -> 96173.032 | G44: =SUM(H38:S38) -> 99838.692 | H44: =SUM(I38:T38) -> 103512.49 | I44: =SUM(J38:U38) -> 107194.44 | J44: =SUM(K38:V38) -> 110602.55 | K44: =SUM(L38:W38) -> 113736.83 | ... DG44: =SUM(DH38:DS38) -> 172370.28 | DH44: =SUM(CW38:DH38) -> 166617.57 | DI44: =SUM(CX38:DI38) -> 167140.54 | DJ44: =SUM(CY38:DJ38) -> 167663.52 | DK44: =SUM(CZ38:DK38) -> 168186.49 | DL44: =SUM(DA38:DL38) -> 168709.46 | DM44: =SUM(DB38:DM38) -> 169232.44 | DN44: =SUM(DC38:DN38) -> 169755.41 | DO44: =SUM(DD38:DO38) -> 170278.38 | ... DS44: =SUM(DH38:DS38) -> 172370.28

Sheet Debt Schedule
A1: DEBT SCHEDULE — MONTHLY
A2: Initial loan (IO then amortizing) paid off at refinance; refinance loan runs to exit. DSCR / Debt Yield / LTV tracked.
A4: Month # | D4: 1 | E4: 2 | F4: 3 | G4: 4 | H4: 5 | I4: 6 | J4: 7 | K4: 8 | L4: 9 | M4: 10 | N4: 11 | O4: 12 | P4: 13 | Q4: 14 | R4: 15 | S4: 16 | T4: 17 | U4: 18 | V4: 19 | W4: 20 | X4: 21 | Y4: 22 | Z4: 23 | AA4: 24 | AB4: 25 | AC4: 26 | AD4: 27 | AE4: 28 | AF4: 29 | AG4: 30 | AH4: 31 | AI4: 32 | AJ4: 33 | AK4: 34 | AL4: 35 | AM4: 36 | AN4: 37 | AO4: 38 | AP4: 39 | AQ4: 40 | AR4: 41 | AS4: 42 | AT4: 43 | AU4: 44 | AV4: 45 | AW4: 46 | AX4: 47 | AY4: 48 | AZ4: 49 | BA4: 50 | BB4: 51 | BC4: 52 | BD4: 53 | BE4: 54 | BF4: 55 | BG4: 56 | BH4: 57 | BI4: 58 | BJ4: 59 | BK4: 60 | BL4: 61 | BM4: 62 | BN4: 63 | BO4: 64 | BP4: 65 | BQ4: 66 | BR4: 67 | BS4: 68 | BT4: 69 | BU4: 70 | BV4: 71 | BW4: 72 | BX4: 73 | BY4: 74 | BZ4: 75 | CA4: 76 | CB4: 77 | CC4: 78 | CD4: 79 | CE4: 80 | CF4: 81 | CG4: 82 | CH4: 83 | CI4: 84 | CJ4: 85 | CK4: 86 | CL4: 87 | CM4: 88 | CN4: 89 | CO4: 90 | CP4: 91 | CQ4: 92 | CR4: 93 | CS4: 94 | CT4: 95 | CU4: 96 | CV4: 97 | CW4: 98 | CX4: 99 | CY4: 100 | CZ4: 101 | DA4: 102 | DB4: 103 | DC4: 104 | DD4: 105 | DE4: 106 | DF4: 107 | DG4: 108 | DH4: 109 | DI4: 110 | DJ4: 111 | DK4: 112 | DL4: 113 | DM4: 114 | DN4: 115 | DO4: 116 | DP4: 117 | DQ4: 118 | DR4: 119 | DS4: 120
A5: INITIAL LOAN | AL5: .
A6: Initial — Beg Balance | D6: =IF(D4<IF(Assumptions!$B$67=1,Assumptions!$B$68,Assumptions!$B$60+1),Acquisition!$B$10,0) -> 910000 | E6: =IF(E4<IF(Assumptions!$B$67=1,Assumptions!$B$68,Assumptions!$B$60+1),D10,0) -> 910000 | F6: =IF(F4<IF(Assumptions!$B$67=1,Assumptions!$B$68,Assumptions!$B$60+1),E10,0) -> 910000 | G6: =IF(G4<IF(Assumptions!$B$67=1,Assumptions!$B$68,Assumptions!$B$60+1),F10,0) -> 910000 | H6: =IF(H4<IF(Assumptions!$B$67=1,Assumptions!$B$68,Assumptions!$B$60+1),G10,0) -> 910000 | I6: =IF(I4<IF(Assumptions!$B$67=1,Assumptions!$B$68,Assumptions!$B$60+1),H10,0) -> 910000 | J6: =IF(J4<IF(Assumptions!$B$67=1,Assumptions!$B$68,Assumptions!$B$60+1),I10,0) -> 910000 | K6: =IF(K4<IF(Assumptions!$B$67=1,Assumptions!$B$68,Assumptions!$B$60+1),J10,0) -> 910000 | L6: =IF(L4<IF(Assumptions!$B$67=1,Assumptions!$B$68,Assumptions!$B$60+1),K10,0) -> 910000 | ... DS6: =IF(DS4<IF(Assumptions!$B$67=1,Assumptions!$B$68,Assumptions!$B$60+1),DR10,0) -> 0
A7: Interest | D7: =IF(D4<IF(Assumptions!$B$67=1,Assumptions!$B$68,Assumptions!$B$60+1),D6*Assumptions!$B$88,0) -> 4929.1667 | E7: =IF(E4<IF(Assumptions!$B$67=1,Assumptions!$B$68,Assumptions!$B$60+1),E6*Assumptions!$B$88,0) -> 4929.1667 | F7: =IF(F4<IF(Assumptions!$B$67=1,Assumptions!$B$68,Assumptions!$B$60+1),F6*Assumptions!$B$88,0) -> 4929.1667 | G7: =IF(G4<IF(Assumptions!$B$67=1,Assumptions!$B$68,Assumptions!$B$60+1),G6*Assumptions!$B$88,0) -> 4929.1667 | H7: =IF(H4<IF(Assumptions!$B$67=1,Assumptions!$B$68,Assumptions!$B$60+1),H6*Assumptions!$B$88,0) -> 4929.1667 | I7: =IF(I4<IF(Assumptions!$B$67=1,Assumptions!$B$68,Assumptions!$B$60+1),I6*Assumptions!$B$88,0) -> 4929.1667 | J7: =IF(J4<IF(Assumptions!$B$67=1,Assumptions!$B$68,Assumptions!$B$60+1),J6*Assumptions!$B$88,0) -> 4929.1667 | K7: =IF(K4<IF(Assumptions!$B$67=1,Assumptions!$B$68,Assumptions!$B$60+1),K6*Assumptions!$B$88,0) -> 4929.1667 | ... DS7: =IF(DS4<IF(Assumptions!$B$67=1,Assumptions!$B$68,Assumptions!$B$60+1),DS6*Assumptions!$B$88,0) -> 0
A8: Principal | D8: =IF(D4<IF(Assumptions!$B$67=1,Assumptions!$B$68,Assumptions!$B$60+1),IF(D4<=Assumptions!$B$61,0,(-PMT(Assumptions!$B$88,Assumptions!$B$59,Acquisition!$B$10))-D7),0) -> 0 | E8: =IF(E4<IF(Assumptions!$B$67=1,Assumptions!$B$68,Assumptions!$B$60+1),IF(E4<=Assumptions!$B$61,0,(-PMT(Assumptions!$B$88,Assumptions!$B$59,Acquisition!$B$10))-E7),0) -> 0 | F8: =IF(F4<IF(Assumptions!$B$67=1,Assumptions!$B$68,Assumptions!$B$60+1),IF(F4<=Assumptions!$B$61,0,(-PMT(Assumptions!$B$88,Assumptions!$B$59,Acquisition!$B$10))-F7),0) -> 0 | G8: =IF(G4<IF(Assumptions!$B$67=1,Assumptions!$B$68,Assumptions!$B$60+1),IF(G4<=Assumptions!$B$61,0,(-PMT(Assumptions!$B$88,Assumptions!$B$59,Acquisition!$B$10))-G7),0) -> 0 | H8: =IF(H4<IF(Assumptions!$B$67=1,Assumptions!$B$68,Assumptions!$B$60+1),IF(H4<=Assumptions!$B$61,0,(-PMT(Assumptions!$B$88,Assumptions!$B$59,Acquisition!$B$10))-H7),0) -> 0 | I8: =IF(I4<IF(Assumptions!$B$67=1,Assumptions!$B$68,Assumptions!$B$60+1),IF(I4<=Assumptions!$B$61,0,(-PMT(Assumptions!$B$88,Assumptions!$B$59,Acquisition!$B$10))-I7),0) -> 0 | J8: =IF(J4<IF(Assumptions!$B$67=1,Assumptions!$B$68,Assumptions!$B$60+1),IF(J4<=Assumptions!$B$61,0,(-PMT(Assumptions!$B$88,Assumptions!$B$59,Acquisition!$B$10))-J7),0) -> 0 | K8: =IF(K4<IF(Assumptions!$B$67=1,Assumptions!$B$68,Assumptions!$B$60+1),IF(K4<=Assumptions!$B$61,0,(-PMT(Assumptions!$B$88,Assumptions!$B$59,Acquisition!$B$10))-K7),0) -> 0 | ... DS8: =IF(DS4<IF(Assumptions!$B$67=1,Assumptions!$B$68,Assumptions!$B$60+1),IF(DS4<=Assumptions!$B$61,0,(-PMT(Assumptions!$B$88,Assumptions!$B$59,Acquisition!$B$10))-DS7),0) -> 0
A9: Debt Service | D9: =D7+D8 -> 4929.1667 | E9: =E7+E8 -> 4929.1667 | F9: =F7+F8 -> 4929.1667 | G9: =G7+G8 -> 4929.1667 | H9: =H7+H8 -> 4929.1667 | I9: =I7+I8 -> 4929.1667 | J9: =J7+J8 -> 4929.1667 | K9: =K7+K8 -> 4929.1667 | ... DS9: =DS7+DS8 -> 0
A10: Initial — End Balance | D10: =D6-D8 -> 910000 | E10: =E6-E8 -> 910000 | F10: =F6-F8 -> 910000 | G10: =G6-G8 -> 910000 | H10: =H6-H8 -> 910000 | I10: =I6-I8 -> 910000 | J10: =J6-J8 -> 910000 | K10: =K6-K8 -> 910000 | ... DS10: =DS6-DS8 -> 0
A11: REFINANCE LOAN
A12: Refi — Beg Balance | D12: =IF(AND(Assumptions!$B$67=1,D4>=Assumptions!$B$68,D4<=Assumptions!$B$68+Assumptions!$B$60),Refinance!$B$11,0) -> 0 | E12: =IF(AND(Assumptions!$B$67=1,E4>=Assumptions!$B$68,E4<=Assumptions!$B$68+Assumptions!$B$60),IF(E4=Assumptions!$B$68,Refinance!$B$11,D16),0) -> 0 | F12: =IF(AND(Assumptions!$B$67=1,F4>=Assumptions!$B$68,F4<=Assumptions!$B$68+Assumptions!$B$60),IF(F4=Assumptions!$B$68,Refinance!$B$11,E16),0) -> 0 | G12: =IF(AND(Assumptions!$B$67=1,G4>=Assumptions!$B$68,G4<=Assumptions!$B$68+Assumptions!$B$60),IF(G4=Assumptions!$B$68,Refinance!$B$11,F16),0) -> 0 | H12: =IF(AND(Assumptions!$B$67=1,H4>=Assumptions!$B$68,H4<=Assumptions!$B$68+Assumptions!$B$60),IF(H4=Assumptions!$B$68,Refinance!$B$11,G16),0) -> 0 | I12: =IF(AND(Assumptions!$B$67=1,I4>=Assumptions!$B$68,I4<=Assumptions!$B$68+Assumptions!$B$60),IF(I4=Assumptions!$B$68,Refinance!$B$11,H16),0) -> 0 | J12: =IF(AND(Assumptions!$B$67=1,J4>=Assumptions!$B$68,J4<=Assumptions!$B$68+Assumptions!$B$60),IF(J4=Assumptions!$B$68,Refinance!$B$11,I16),0) -> 0 | K12: =IF(AND(Assumptions!$B$67=1,K4>=Assumptions!$B$68,K4<=Assumptions!$B$68+Assumptions!$B$60),IF(K4=Assumptions!$B$68,Refinance!$B$11,J16),0) -> 0 | L12: =IF(AND(Assumptions!$B$67=1,L4>=Assumptions!$B$68,L4<=Assumptions!$B$68+Assumptions!$B$60),IF(L4=Assumptions!$B$68,Refinance!$B$11,K16),0) -> 0 | ... DS12: =IF(AND(Assumptions!$B$67=1,DS4>=Assumptions!$B$68,DS4<=Assumptions!$B$68+Assumptions!$B$60),IF(DS4=Assumptions!$B$68,Refinance!$B$11,DR16),0) -> 1373320.5
A13: Interest | D13: =IF(AND(Assumptions!$B$67=1,D4>=Assumptions!$B$68,D4<=Assumptions!$B$68+Assumptions!$B$60),D12*Assumptions!$B$89,0) -> 0 | E13: =IF(AND(Assumptions!$B$67=1,E4>=Assumptions!$B$68,E4<=Assumptions!$B$68+Assumptions!$B$60),E12*Assumptions!$B$89,0) -> 0 | F13: =IF(AND(Assumptions!$B$67=1,F4>=Assumptions!$B$68,F4<=Assumptions!$B$68+Assumptions!$B$60),F12*Assumptions!$B$89,0) -> 0 | G13: =IF(AND(Assumptions!$B$67=1,G4>=Assumptions!$B$68,G4<=Assumptions!$B$68+Assumptions!$B$60),G12*Assumptions!$B$89,0) -> 0 | H13: =IF(AND(Assumptions!$B$67=1,H4>=Assumptions!$B$68,H4<=Assumptions!$B$68+Assumptions!$B$60),H12*Assumptions!$B$89,0) -> 0 | I13: =IF(AND(Assumptions!$B$67=1,I4>=Assumptions!$B$68,I4<=Assumptions!$B$68+Assumptions!$B$60),I12*Assumptions!$B$89,0) -> 0 | J13: =IF(AND(Assumptions!$B$67=1,J4>=Assumptions!$B$68,J4<=Assumptions!$B$68+Assumptions!$B$60),J12*Assumptions!$B$89,0) -> 0 | K13: =IF(AND(Assumptions!$B$67=1,K4>=Assumptions!$B$68,K4<=Assumptions!$B$68+Assumptions!$B$60),K12*Assumptions!$B$89,0) -> 0 | ... DS13: =IF(AND(Assumptions!$B$67=1,DS4>=Assumptions!$B$68,DS4<=Assumptions!$B$68+Assumptions!$B$60),DS12*Assumptions!$B$89,0) -> 6866.6027
A14: Principal | D14: =IF(AND(Assumptions!$B$67=1,D4>=Assumptions!$B$68,D4<=Assumptions!$B$68+Assumptions!$B$60),IF(D4<Assumptions!$B$68+Assumptions!$B$72,0,(-PMT(Assumptions!$B$89,Assumptions!$B$71,Refinance!$B$11))-D13),0) -> 0 | E14: =IF(AND(Assumptions!$B$67=1,E4>=Assumptions!$B$68,E4<=Assumptions!$B$68+Assumptions!$B$60),IF(E4<Assumptions!$B$68+Assumptions!$B$72,0,(-PMT(Assumptions!$B$89,Assumptions!$B$71,Refinance!$B$11))-E13),0) -> 0 | F14: =IF(AND(Assumptions!$B$67=1,F4>=Assumptions!$B$68,F4<=Assumptions!$B$68+Assumptions!$B$60),IF(F4<Assumptions!$B$68+Assumptions!$B$72,0,(-PMT(Assumptions!$B$89,Assumptions!$B$71,Refinance!$B$11))-F13),0) -> 0 | G14: =IF(AND(Assumptions!$B$67=1,G4>=Assumptions!$B$68,G4<=Assumptions!$B$68+Assumptions!$B$60),IF(G4<Assumptions!$B$68+Assumptions!$B$72,0,(-PMT(Assumptions!$B$89,Assumptions!$B$71,Refinance!$B$11))-G13),0) -> 0 | H14: =IF(AND(Assumptions!$B$67=1,H4>=Assumptions!$B$68,H4<=Assumptions!$B$68+Assumptions!$B$60),IF(H4<Assumptions!$B$68+Assumptions!$B$72,0,(-PMT(Assumptions!$B$89,Assumptions!$B$71,Refinance!$B$11))-H13),0) -> 0 | I14: =IF(AND(Assumptions!$B$67=1,I4>=Assumptions!$B$68,I4<=Assumptions!$B$68+Assumptions!$B$60),IF(I4<Assumptions!$B$68+Assumptions!$B$72,0,(-PMT(Assumptions!$B$89,Assumptions!$B$71,Refinance!$B$11))-I13),0) -> 0 | J14: =IF(AND(Assumptions!$B$67=1,J4>=Assumptions!$B$68,J4<=Assumptions!$B$68+Assumptions!$B$60),IF(J4<Assumptions!$B$68+Assumptions!$B$72,0,(-PMT(Assumptions!$B$89,Assumptions!$B$71,Refinance!$B$11))-J13),0) -> 0 | K14: =IF(AND(Assumptions!$B$67=1,K4>=Assumptions!$B$68,K4<=Assumptions!$B$68+Assumptions!$B$60),IF(K4<Assumptions!$B$68+Assumptions!$B$72,0,(-PMT(Assumptions!$B$89,Assumptions!$B$71,Refinance!$B$11))-K13),0) -> 0 | ... DS14: =IF(AND(Assumptions!$B$67=1,DS4>=Assumptions!$B$68,DS4<=Assumptions!$B$68+Assumptions!$B$60),IF(DS4<Assumptions!$B$68+Assumptions!$B$72,0,(-PMT(Assumptions!$B$89,Assumptions!$B$71,Refinance!$B$11))-DS13),0) -> 2318.8133
A15: Debt Service | D15: =D13+D14 -> 0 | E15: =E13+E14 -> 0 | F15: =F13+F14 -> 0 | G15: =G13+G14 -> 0 | H15: =H13+H14 -> 0 | I15: =I13+I14 -> 0 | J15: =J13+J14 -> 0 | K15: =K13+K14 -> 0 | ... DS15: =DS13+DS14 -> 9185.416
